Workbook

Sheet Informações
A1: Informações gerais
A3: Em caso de férias:
A4: Não preencha na planilha os dias em que não trabalhou.
A5: Envie sua planilha de horas em seu último dia de trabalho antes de suas férias iniciarem.
A8: Em caso de falta, atrasos ou saídas antecipadas:
A9: Preencha na planilha apenas as horas que realmente trabalhou, sem considerar as horas contidas em atestado médico ou odontológico.
A10: Coloque na coluna Descrição das Atividades que possui atestado médico e envie o atestado digitalizado junto com a planilha.
A11: Faltas, atrasos ou saídas antecipadas sem justificação, serão descontados.
A13: A planilha de apontamento deve ser mensalmente enviada para horas@gtisolution.com.br no primeiro dia útil do mês seguinte, com todas as informações do mês anterior.
A16: Horas extras (durante semana ou em feriados e finais de semana) apenas podem ser realizadas com autorização prévia de sua coordenação/gerência.
A17: Horas extras autorizadas e trabalhadas são pagas sempre no mês seguinte ao mês em que horas realizadas.

Sheet Janeiro_22
A1: Dia | B1: Dia da Semana | C1: Entrada | D1: Almoço | E1: Retorno | F1: Saída | G1: Total Horas | H1: Horas Normais | I1: Horas 75% | J1: Horas 100% | K1: Adic. Noturno | M1: Descrição das Atividades
L2: Convert
A3: 44562 | B3: =A3 -> 44562 | C3: 0 | D3: 0 | E3: 0 | F3: 0 | G3: =IF(A3=" "," ",(D3-C3)+(F3-E3)) -> 0 | H3: {=IF(OR(WEEKDAY(A3)=1,WEEKDAY(A3)=7,'.'!A:A=A3),TIME(0,0,0),IF((G3*24)>8,TIME(8,0,0),G3))} -> 0 | I3: {=IF(OR(WEEKDAY(A3)=1,WEEKDAY(A3)=7,'.'!A:A=A3),TIME(0,0,0),IF((G3*24)>10,TIME(2,0,0),IF((G3*24)<=8,TIME(0,0,0),G3-TIME(8,0,0))))} -> 0 | J3: {=IF(OR(WEEKDAY(A3)=1,WEEKDAY(A3)=7,'.'!A:A=A3),G3,IF((G3*24)>10,IF((G3*24)<=10,TIME(0,0,0),G3-TIME(10,0,0)),TIME(0,0,0)))} -> 0 | K3: =IF((G3*24)=0,TIME(0,0,0),IF((C3*24)<6,TIME(6-(C3*24),0,0),TIME(0,0,0))+IF((F3*24)>22,F3-TIME(22,0,0),TIME(0,0,0))) -> 0 | L3: =IF(A3=" "," ",((H3*24)+(I3*24*1.75)+(J3*24*2)+(K3*24*0.3))) -> 0 | M3: Confraternização Universal
A4: 44563 | B4: =A4 -> 44563 | C4: 0 | D4: 0 | E4: 0 | F4: 0 | G4: =IF(A4=" "," ",(D4-C4)+(F4-E4)) -> 0 | H4: {=IF(OR(WEEKDAY(A4)=1,WEEKDAY(A4)=7,'.'!A:A=A4),TIME(0,0,0),IF((G4*24)>8,TIME(8,0,0),G4))} -> 0 | I4: {=IF(OR(WEEKDAY(A4)=1,WEEKDAY(A4)=7,'.'!A:A=A4),TIME(0,0,0),IF((G4*24)>10,TIME(2,0,0),IF((G4*24)<=8,TIME(0,0,0),G4-TIME(8,0,0))))} -> 0 | J4: {=IF(OR(WEEKDAY(A4)=1,WEEKDAY(A4)=7,'.'!A:A=A4),G4,IF((G4*24)>10,IF((G4*24)<=10,TIME(0,0,0),G4-TIME(10,0,0)),TIME(0,0,0)))} -> 0 | K4: =IF((G4*24)=0,TIME(0,0,0),IF((C4*24)<6,TIME(6-(C4*24),0,0),TIME(0,0,0))+IF((F4*24)>22,F4-TIME(22,0,0),TIME(0,0,0))) -> 0 | L4: =IF(A4=" "," ",((H4*24)+(I4*24*1.75)+(J4*24*2)+(K4*24*0.3))) -> 0
A5: 44564 | B5: =A5 -> 44564 | C5: 0 | D5: 0 | E5: 0 | F5: 0 | G5: =IF(A5=" "," ",(D5-C5)+(F5-E5)) -> 0 | H5: {=IF(OR(WEEKDAY(A5)=1,WEEKDAY(A5)=7,'.'!A:A=A5),TIME(0,0,0),IF((G5*24)>8,TIME(8,0,0),G5))} -> 0 | I5: {=IF(OR(WEEKDAY(A5)=1,WEEKDAY(A5)=7,'.'!A:A=A5),TIME(0,0,0),IF((G5*24)>10,TIME(2,0,0),IF((G5*24)<=8,TIME(0,0,0),G5-TIME(8,0,0))))} -> 0 | J5: {=IF(OR(WEEKDAY(A5)=1,WEEKDAY(A5)=7,'.'!A:A=A5),G5,IF((G5*24)>10,IF((G5*24)<=10,TIME(0,0,0),G5-TIME(10,0,0)),TIME(0,0,0)))} -> 0 | K5: =IF((G5*24)=0,TIME(0,0,0),IF((C5*24)<6,TIME(6-(C5*24),0,0),TIME(0,0,0))+IF((F5*24)>22,F5-TIME(22,0,0),TIME(0,0,0))) -> 0 | L5: =IF(A5=" "," ",((H5*24)+(I5*24*1.75)+(J5*24*2)+(K5*24*0.3))) -> 0
A6: 44565 | B6: =A6 -> 44565 | C6: 0 | D6: 0 | E6: 0 | F6: 0 | G6: =IF(A6=" "," ",(D6-C6)+(F6-E6)) -> 0 | H6: {=IF(OR(WEEKDAY(A6)=1,WEEKDAY(A6)=7,'.'!A:A=A6),TIME(0,0,0),IF((G6*24)>8,TIME(8,0,0),G6))} -> 0 | I6: {=IF(OR(WEEKDAY(A6)=1,WEEKDAY(A6)=7,'.'!A:A=A6),TIME(0,0,0),IF((G6*24)>10,TIME(2,0,0),IF((G6*24)<=8,TIME(0,0,0),G6-TIME(8,0,0))))} -> 0 | J6: {=IF(OR(WEEKDAY(A6)=1,WEEKDAY(A6)=7,'.'!A:A=A6),G6,IF((G6*24)>10,IF((G6*24)<=10,TIME(0,0,0),G6-TIME(10,0,0)),TIME(0,0,0)))} -> 0 | K6: =IF((G6*24)=0,TIME(0,0,0),IF((C6*24)<6,TIME(6-(C6*24),0,0),TIME(0,0,0))+IF((F6*24)>22,F6-TIME(22,0,0),TIME(0,0,0))) -> 0 | L6: =IF(A6=" "," ",((H6*24)+(I6*24*1.75)+(J6*24*2)+(K6*24*0.3))) -> 0
A7: 44566 | B7: =A7 -> 44566 | C7: 0 | D7: 0 | E7: 0 | F7: 0 | G7: =IF(A7=" "," ",(D7-C7)+(F7-E7)) -> 0 | H7: {=IF(OR(WEEKDAY(A7)=1,WEEKDAY(A7)=7,'.'!A:A=A7),TIME(0,0,0),IF((G7*24)>8,TIME(8,0,0),G7))} -> 0 | I7: {=IF(OR(WEEKDAY(A7)=1,WEEKDAY(A7)=7,'.'!A:A=A7),TIME(0,0,0),IF((G7*24)>10,TIME(2,0,0),IF((G7*24)<=8,TIME(0,0,0),G7-TIME(8,0,0))))} -> 0 | J7: {=IF(OR(WEEKDAY(A7)=1,WEEKDAY(A7)=7,'.'!A:A=A7),G7,IF((G7*24)>10,IF((G7*24)<=10,TIME(0,0,0),G7-TIME(10,0,0)),TIME(0,0,0)))} -> 0 | K7: =IF((G7*24)=0,TIME(0,0,0),IF((C7*24)<6,TIME(6-(C7*24),0,0),TIME(0,0,0))+IF((F7*24)>22,F7-TIME(22,0,0),TIME(0,0,0))) -> 0 | L7: =IF(A7=" "," ",((H7*24)+(I7*24*1.75)+(J7*24*2)+(K7*24*0.3))) -> 0
A8: 44567 | B8: =A8 -> 44567 | C8: 0 | D8: 0 | E8: 0 | F8: 0 | G8: =IF(A8=" "," ",(D8-C8)+(F8-E8)) -> 0 | H8: {=IF(OR(WEEKDAY(A8)=1,WEEKDAY(A8)=7,'.'!A:A=A8),TIME(0,0,0),IF((G8*24)>8,TIME(8,0,0),G8))} -> 0 | I8: {=IF(OR(WEEKDAY(A8)=1,WEEKDAY(A8)=7,'.'!A:A=A8),TIME(0,0,0),IF((G8*24)>10,TIME(2,0,0),IF((G8*24)<=8,TIME(0,0,0),G8-TIME(8,0,0))))} -> 0 | J8: {=IF(OR(WEEKDAY(A8)=1,WEEKDAY(A8)=7,'.'!A:A=A8),G8,IF((G8*24)>10,IF((G8*24)<=10,TIME(0,0,0),G8-TIME(10,0,0)),TIME(0,0,0)))} -> 0 | K8: =IF((G8*24)=0,TIME(0,0,0),IF((C8*24)<6,TIME(6-(C8*24),0,0),TIME(0,0,0))+IF((F8*24)>22,F8-TIME(22,0,0),TIME(0,0,0))) -> 0 | L8: =IF(A8=" "," ",((H8*24)+(I8*24*1.75)+(J8*24*2)+(K8*24*0.3))) -> 0
A9: 44568 | B9: =A9 -> 44568 | C9: 0 | D9: 0 | E9: 0 | F9: 0 | G9: =IF(A9=" "," ",(D9-C9)+(F9-E9)) -> 0 | H9: {=IF(OR(WEEKDAY(A9)=1,WEEKDAY(A9)=7,'.'!A:A=A9),TIME(0,0,0),IF((G9*24)>8,TIME(8,0,0),G9))} -> 0 | I9: {=IF(OR(WEEKDAY(A9)=1,WEEKDAY(A9)=7,'.'!A:A=A9),TIME(0,0,0),IF((G9*24)>10,TIME(2,0,0),IF((G9*24)<=8,TIME(0,0,0),G9-TIME(8,0,0))))} -> 0 | J9: {=IF(OR(WEEKDAY(A9)=1,WEEKDAY(A9)=7,'.'!A:A=A9),G9,IF((G9*24)>10,IF((G9*24)<=10,TIME(0,0,0),G9-TIME(10,0,0)),TIME(0,0,0)))} -> 0 | K9: =IF((G9*24)=0,TIME(0,0,0),IF((C9*24)<6,TIME(6-(C9*24),0,0),TIME(0,0,0))+IF((F9*24)>22,F9-TIME(22,0,0),TIME(0,0,0))) -> 0 | L9: =IF(A9=" "," ",((H9*24)+(I9*24*1.75)+(J9*24*2)+(K9*24*0.3))) -> 0
A10: 44569 | B10: =A10 -> 44569 | C10: 0 | D10: 0 | E10: 0 | F10: 0 | G10: =IF(A10=" "," ",(D10-C10)+(F10-E10)) -> 0 | H10: {=IF(OR(WEEKDAY(A10)=1,WEEKDAY(A10)=7,'.'!A:A=A10),TIME(0,0,0),IF((G10*24)>8,TIME(8,0,0),G10))} -> 0 | I10: {=IF(OR(WEEKDAY(A10)=1,WEEKDAY(A10)=7,'.'!A:A=A10),TIME(0,0,0),IF((G10*24)>10,TIME(2,0,0),IF((G10*24)<=8,TIME(0,0,0),G10-TIME(8,0,0))))} -> 0 | J10: {=IF(OR(WEEKDAY(A10)=1,WEEKDAY(A10)=7,'.'!A:A=A10),G10,IF((G10*24)>10,IF((G10*24)<=10,TIME(0,0,0),G10-TIME(10,0,0)),TIME(0,0,0)))} -> 0 | K10: =IF((G10*24)=0,TIME(0,0,0),IF((C10*24)<6,TIME(6-(C10*24),0,0),TIME(0,0,0))+IF((F10*24)>22,F10-TIME(22,0,0),TIME(0,0,0))) -> 0 | L10: =IF(A10=" "," ",((H10*24)+(I10*24*1.75)+(J10*24*2)+(K10*24*0.3))) -> 0
A11: 44570 | B11: =A11 -> 44570 | C11: 0 | D11: 0 | E11: 0 | F11: 0 | G11: =IF(A11=" "," ",(D11-C11)+(F11-E11)) -> 0 | H11: {=IF(OR(WEEKDAY(A11)=1,WEEKDAY(A11)=7,'.'!A:A=A11),TIME(0,0,0),IF((G11*24)>8,TIME(8,0,0),G11))} -> 0 | I11: {=IF(OR(WEEKDAY(A11)=1,WEEKDAY(A11)=7,'.'!A:A=A11),TIME(0,0,0),IF((G11*24)>10,TIME(2,0,0),IF((G11*24)<=8,TIME(0,0,0),G11-TIME(8,0,0))))} -> 0 | J11: {=IF(OR(WEEKDAY(A11)=1,WEEKDAY(A11)=7,'.'!A:A=A11),G11,IF((G11*24)>10,IF((G11*24)<=10,TIME(0,0,0),G11-TIME(10,0,0)),TIME(0,0,0)))} -> 0 | K11: =IF((G11*24)=0,TIME(0,0,0),IF((C11*24)<6,TIME(6-(C11*24),0,0),TIME(0,0,0))+IF((F11*24)>22,F11-TIME(22,0,0),TIME(0,0,0))) -> 0 | L11: =IF(A11=" "," ",((H11*24)+(I11*24*1.75)+(J11*24*2)+(K11*24*0.3))) -> 0
A12: 44571 | B12: =A12 -> 44571 | C12: 0 | D12: 0 | E12: 0 | F12: 0 | G12: =IF(A12=" "," ",(D12-C12)+(F12-E12)) -> 0 | H12: {=IF(OR(WEEKDAY(A12)=1,WEEKDAY(A12)=7,'.'!A:A=A12),TIME(0,0,0),IF((G12*24)>8,TIME(8,0,0),G12))} -> 0 | I12: {=IF(OR(WEEKDAY(A12)=1,WEEKDAY(A12)=7,'.'!A:A=A12),TIME(0,0,0),IF((G12*24)>10,TIME(2,0,0),IF((G12*24)<=8,TIME(0,0,0),G12-TIME(8,0,0))))} -> 0 | J12: {=IF(OR(WEEKDAY(A12)=1,WEEKDAY(A12)=7,'.'!A:A=A12),G12,IF((G12*24)>10,IF((G12*24)<=10,TIME(0,0,0),G12-TIME(10,0,0)),TIME(0,0,0)))} -> 0 | K12: =IF((G12*24)=0,TIME(0,0,0),IF((C12*24)<6,TIME(6-(C12*24),0,0),TIME(0,0,0))+IF((F12*24)>22,F12-TIME(22,0,0),TIME(0,0,0))) -> 0 | L12: =IF(A12=" "," ",((H12*24)+(I12*24*1.75)+(J12*24*2)+(K12*24*0.3))) -> 0
A13: 44572 | B13: =A13 -> 44572 | C13: 0 | D13: 0 | E13: 0 | F13: 0 | G13: =IF(A13=" "," ",(D13-C13)+(F13-E13)) -> 0 | H13: {=IF(OR(WEEKDAY(A13)=1,WEEKDAY(A13)=7,'.'!A:A=A13),TIME(0,0,0),IF((G13*24)>8,TIME(8,0,0),G13))} -> 0 | I13: {=IF(OR(WEEKDAY(A13)=1,WEEKDAY(A13)=7,'.'!A:A=A13),TIME(0,0,0),IF((G13*24)>10,TIME(2,0,0),IF((G13*24)<=8,TIME(0,0,0),G13-TIME(8,0,0))))} -> 0 | J13: {=IF(OR(WEEKDAY(A13)=1,WEEKDAY(A13)=7,'.'!A:A=A13),G13,IF((G13*24)>10,IF((G13*24)<=10,TIME(0,0,0),G13-TIME(10,0,0)),TIME(0,0,0)))} -> 0 | K13: =IF((G13*24)=0,TIME(0,0,0),IF((C13*24)<6,TIME(6-(C13*24),0,0),TIME(0,0,0))+IF((F13*24)>22,F13-TIME(22,0,0),TIME(0,0,0))) -> 0 | L13: =IF(A13=" "," ",((H13*24)+(I13*24*1.75)+(J13*24*2)+(K13*24*0.3))) -> 0
A14: 44573 | B14: =A14 -> 44573 | C14: 0 | D14: 0 | E14: 0 | F14: 0 | G14: =IF(A14=" "," ",(D14-C14)+(F14-E14)) -> 0 | H14: {=IF(OR(WEEKDAY(A14)=1,WEEKDAY(A14)=7,'.'!A:A=A14),TIME(0,0,0),IF((G14*24)>8,TIME(8,0,0),G14))} -> 0 | I14: {=IF(OR(WEEKDAY(A14)=1,WEEKDAY(A14)=7,'.'!A:A=A14),TIME(0,0,0),IF((G14*24)>10,TIME(2,0,0),IF((G14*24)<=8,TIME(0,0,0),G14-TIME(8,0,0))))} -> 0 | J14: {=IF(OR(WEEKDAY(A14)=1,WEEKDAY(A14)=7,'.'!A:A=A14),G14,IF((G14*24)>10,IF((G14*24)<=10,TIME(0,0,0),G14-TIME(10,0,0)),TIME(0,0,0)))} -> 0 | K14: =IF((G14*24)=0,TIME(0,0,0),IF((C14*24)<6,TIME(6-(C14*24),0,0),TIME(0,0,0))+IF((F14*24)>22,F14-TIME(22,0,0),TIME(0,0,0))) -> 0 | L14: =IF(A14=" "," ",((H14*24)+(I14*24*1.75)+(J14*24*2)+(K14*24*0.3))) -> 0
A15: 44574 | B15: =A15 -> 44574 | C15: 0 | D15: 0 | E15: 0 | F15: 0 | G15: =IF(A15=" "," ",(D15-C15)+(F15-E15)) -> 0 | H15: {=IF(OR(WEEKDAY(A15)=1,WEEKDAY(A15)=7,'.'!A:A=A15),TIME(0,0,0),IF((G15*24)>8,TIME(8,0,0),G15))} -> 0 | I15: {=IF(OR(WEEKDAY(A15)=1,WEEKDAY(A15)=7,'.'!A:A=A15),TIME(0,0,0),IF((G15*24)>10,TIME(2,0,0),IF((G15*24)<=8,TIME(0,0,0),G15-TIME(8,0,0))))} -> 0 | J15: {=IF(OR(WEEKDAY(A15)=1,WEEKDAY(A15)=7,'.'!A:A=A15),G15,IF((G15*24)>10,IF((G15*24)<=10,TIME(0,0,0),G15-TIME(10,0,0)),TIME(0,0,0)))} -> 0 | K15: =IF((G15*24)=0,TIME(0,0,0),IF((C15*24)<6,TIME(6-(C15*24),0,0),TIME(0,0,0))+IF((F15*24)>22,F15-TIME(22,0,0),TIME(0,0,0))) -> 0 | L15: =IF(A15=" "," ",((H15*24)+(I15*24*1.75)+(J15*24*2)+(K15*24*0.3))) -> 0
... A26: 44585 | B26: =A26 -> 44585 | C26: 0 | D26: 0 | E26: 0 | F26: 0 | G26: =IF(A26=" "," ",(D26-C26)+(F26-E26)) -> 0 | H26: {=IF(OR(WEEKDAY(A26)=1,WEEKDAY(A26)=7,'.'!A:A=A26),TIME(0,0,0),IF((G26*24)>8,TIME(8,0,0),G26))} -> 0 | I26: {=IF(OR(WEEKDAY(A26)=1,WEEKDAY(A26)=7,'.'!A:A=A26),TIME(0,0,0),IF((G26*24)>10,TIME(2,0,0),IF((G26*24)<=8,TIME(0,0,0),G26-TIME(8,0,0))))} -> 0 | J26: {=IF(OR(WEEKDAY(A26)=1,WEEKDAY(A26)=7,'.'!A:A=A26),G26,IF((G26*24)>10,IF((G26*24)<=10,TIME(0,0,0),G26-TIME(10,0,0)),TIME(0,0,0)))} -> 0 | K26: =IF((G26*24)=0,TIME(0,0,0),IF((C26*24)<6,TIME(6-(C26*24),0,0),TIME(0,0,0))+IF((F26*24)>22,F26-TIME(22,0,0),TIME(0,0,0))) -> 0 | L26: =IF(A26=" "," ",((H26*24)+(I26*24*1.75)+(J26*24*2)+(K26*24*0.3))) -> 0
A27: 44586 | B27: =A27 -> 44586 | C27: 0 | D27: 0 | E27: 0 | F27: 0 | G27: =IF(A27=" "," ",(D27-C27)+(F27-E27)) -> 0 | H27: {=IF(OR(WEEKDAY(A27)=1,WEEKDAY(A27)=7,'.'!A:A=A27),TIME(0,0,0),IF((G27*24)>8,TIME(8,0,0),G27))} -> 0 | I27: {=IF(OR(WEEKDAY(A27)=1,WEEKDAY(A27)=7,'.'!A:A=A27),TIME(0,0,0),IF((G27*24)>10,TIME(2,0,0),IF((G27*24)<=8,TIME(0,0,0),G27-TIME(8,0,0))))} -> 0 | J27: {=IF(OR(WEEKDAY(A27)=1,WEEKDAY(A27)=7,'.'!A:A=A27),G27,IF((G27*24)>10,IF((G27*24)<=10,TIME(0,0,0),G27-TIME(10,0,0)),TIME(0,0,0)))} -> 0 | K27: =IF((G27*24)=0,TIME(0,0,0),IF((C27*24)<6,TIME(6-(C27*24),0,0),TIME(0,0,0))+IF((F27*24)>22,F27-TIME(22,0,0),TIME(0,0,0))) -> 0 | L27: =IF(A27=" "," ",((H27*24)+(I27*24*1.75)+(J27*24*2)+(K27*24*0.3))) -> 0 | M27: Aniversário da cidade de São Paulo
A28: 44587 | B28: =A28 -> 44587 | C28: 0 | D28: 0 | E28: 0 | F28: 0 | G28: =IF(A28=" "," ",(D28-C28)+(F28-E28)) -> 0 | H28: {=IF(OR(WEEKDAY(A28)=1,WEEKDAY(A28)=7,'.'!A:A=A28),TIME(0,0,0),IF((G28*24)>8,TIME(8,0,0),G28))} -> 0 | I28: {=IF(OR(WEEKDAY(A28)=1,WEEKDAY(A28)=7,'.'!A:A=A28),TIME(0,0,0),IF((G28*24)>10,TIME(2,0,0),IF((G28*24)<=8,TIME(0,0,0),G28-TIME(8,0,0))))} -> 0 | J28: {=IF(OR(WEEKDAY(A28)=1,WEEKDAY(A28)=7,'.'!A:A=A28),G28,IF((G28*24)>10,IF((G28*24)<=10,TIME(0,0,0),G28-TIME(10,0,0)),TIME(0,0,0)))} -> 0 | K28: =IF((G28*24)=0,TIME(0,0,0),IF((C28*24)<6,TIME(6-(C28*24),0,0),TIME(0,0,0))+IF((F28*24)>22,F28-TIME(22,0,0),TIME(0,0,0))) -> 0 | L28: =IF(A28=" "," ",((H28*24)+(I28*24*1.75)+(J28*24*2)+(K28*24*0.3))) -> 0
A29: 44588 | B29: =A29 -> 44588 | C29: 0 | D29: 0 | E29: 0 | F29: 0 | G29: =IF(A29=" "," ",(D29-C29)+(F29-E29)) -> 0 | H29: {=IF(OR(WEEKDAY(A29)=1,WEEKDAY(A29)=7,'.'!A:A=A29),TIME(0,0,0),IF((G29*24)>8,TIME(8,0,0),G29))} -> 0 | I29: {=IF(OR(WEEKDAY(A29)=1,WEEKDAY(A29)=7,'.'!A:A=A29),TIME(0,0,0),IF((G29*24)>10,TIME(2,0,0),IF((G29*24)<=8,TIME(0,0,0),G29-TIME(8,0,0))))} -> 0 | J29: {=IF(OR(WEEKDAY(A29)=1,WEEKDAY(A29)=7,'.'!A:A=A29),G29,IF((G29*24)>10,IF((G29*24)<=10,TIME(0,0,0),G29-TIME(10,0,0)),TIME(0,0,0)))} -> 0 | K29: =IF((G29*24)=0,TIME(0,0,0),IF((C29*24)<6,TIME(6-(C29*24),0,0),TIME(0,0,0))+IF((F29*24)>22,F29-TIME(22,0,0),TIME(0,0,0))) -> 0 | L29: =IF(A29=" "," ",((H29*24)+(I29*24*1.75)+(J29*24*2)+(K29*24*0.3))) -> 0
A30: 44589 | B30: =A30 -> 44589 | C30: 0 | D30: 0 | E30: 0 | F30: 0 | G30: =IF(A30=" "," ",(D30-C30)+(F30-E30)) -> 0 | H30: {=IF(OR(WEEKDAY(A30)=1,WEEKDAY(A30)=7,'.'!A:A=A30),TIME(0,0,0),IF((G30*24)>8,TIME(8,0,0),G30))} -> 0 | I30: {=IF(OR(WEEKDAY(A30)=1,WEEKDAY(A30)=7,'.'!A:A=A30),TIME(0,0,0),IF((G30*24)>10,TIME(2,0,0),IF((G30*24)<=8,TIME(0,0,0),G30-TIME(8,0,0))))} -> 0 | J30: {=IF(OR(WEEKDAY(A30)=1,WEEKDAY(A30)=7,'.'!A:A=A30),G30,IF((G30*24)>10,IF((G30*24)<=10,TIME(0,0,0),G30-TIME(10,0,0)),TIME(0,0,0)))} -> 0 | K30: =IF((G30*24)=0,TIME(0,0,0),IF((C30*24)<6,TIME(6-(C30*24),0,0),TIME(0,0,0))+IF((F30*24)>22,F30-TIME(22,0,0),TIME(0,0,0))) -> 0 | L30: =IF(A30=" "," ",((H30*24)+(I30*24*1.75)+(J30*24*2)+(K30*24*0.3))) -> 0
A31: 44590 | B31: =A31 -> 44590 | C31: 0 | D31: 0 | E31: 0 | F31: 0 | G31: =IF(A31=" "," ",(D31-C31)+(F31-E31)) -> 0 | H31: {=IF(OR(WEEKDAY(A31)=1,WEEKDAY(A31)=7,'.'!A:A=A31),TIME(0,0,0),IF((G31*24)>8,TIME(8,0,0),G31))} -> 0 | I31: {=IF(OR(WEEKDAY(A31)=1,WEEKDAY(A31)=7,'.'!A:A=A31),TIME(0,0,0),IF((G31*24)>10,TIME(2,0,0),IF((G31*24)<=8,TIME(0,0,0),G31-TIME(8,0,0))))} -> 0 | J31: {=IF(OR(WEEKDAY(A31)=1,WEEKDAY(A31)=7,'.'!A:A=A31),G31,IF((G31*24)>10,IF((G31*24)<=10,TIME(0,0,0),G31-TIME(10,0,0)),TIME(0,0,0)))} -> 0 | K31: =IF((G31*24)=0,TIME(0,0,0),IF((C31*24)<6,TIME(6-(C31*24),0,0),TIME(0,0,0))+IF((F31*24)>22,F31-TIME(22,0,0),TIME(0,0,0))) -> 0 | L31: =IF(A31=" "," ",((H31*24)+(I31*24*1.75)+(J31*24*2)+(K31*24*0.3))) -> 0
A32: 44591 | B32: =A32 -> 44591 | C32: 0 | D32: 0 | E32: 0 | F32: 0 | G32: =IF(A32=" "," ",(D32-C32)+(F32-E32)) -> 0 | H32: {=IF(OR(WEEKDAY(A32)=1,WEEKDAY(A32)=7,'.'!A:A=A32),TIME(0,0,0),IF((G32*24)>8,TIME(8,0,0),G32))} -> 0 | I32: {=IF(OR(WEEKDAY(A32)=1,WEEKDAY(A32)=7,'.'!A:A=A32),TIME(0,0,0),IF((G32*24)>10,TIME(2,0,0),IF((G32*24)<=8,TIME(0,0,0),G32-TIME(8,0,0))))} -> 0 | J32: {=IF(OR(WEEKDAY(A32)=1,WEEKDAY(A32)=7,'.'!A:A=A32),G32,IF((G32*24)>10,IF((G32*24)<=10,TIME(0,0,0),G32-TIME(10,0,0)),TIME(0,0,0)))} -> 0 | K32: =IF((G32*24)=0,TIME(0,0,0),IF((C32*24)<6,TIME(6-(C32*24),0,0),TIME(0,0,0))+IF((F32*24)>22,F32-TIME(22,0,0),TIME(0,0,0))) -> 0 | L32: =IF(A32=" "," ",((H32*24)+(I32*24*1.75)+(J32*24*2)+(K32*24*0.3))) -> 0
A33: 44592 | B33: =A33 -> 44592 | C33: 0 | D33: 0 | E33: 0 | F33: 0 | G33: =IF(A33=" "," ",(D33-C33)+(F33-E33)) -> 0 | H33: {=IF(OR(WEEKDAY(A33)=1,WEEKDAY(A33)=7,'.'!A:A=A33),TIME(0,0,0),IF((G33*24)>8,TIME(8,0,0),G33))} -> 0 | I33: {=IF(OR(WEEKDAY(A33)=1,WEEKDAY(A33)=7,'.'!A:A=A33),TIME(0,0,0),IF((G33*24)>10,TIME(2,0,0),IF((G33*24)<=8,TIME(0,0,0),G33-TIME(8,0,0))))} -> 0 | J33: {=IF(OR(WEEKDAY(A33)=1,WEEKDAY(A33)=7,'.'!A:A=A33),G33,IF((G33*24)>10,IF((G33*24)<=10,TIME(0,0,0),G33-TIME(10,0,0)),TIME(0,0,0)))} -> 0 | K33: =IF((G33*24)=0,TIME(0,0,0),IF((C33*24)<6,TIME(6-(C33*24),0,0),TIME(0,0,0))+IF((F33*24)>22,F33-TIME(22,0,0),TIME(0,0,0))) -> 0 | L33: =IF(A33=" "," ",((H33*24)+(I33*24*1.75)+(J33*24*2)+(K33*24*0.3))) -> 0
A34: Totais | G34: =SUM(G3:G33)*24 -> 0 | H34: =SUM(H3:H33)*24 -> 0 | I34: =SUM(I3:I33)*24 -> 0 | J34: =SUM(J3:J33)*24 -> 0 | K34: =SUM(K3:K33)*24 -> 0
A35: Total de horas carregadas com adicionais | H35: =H34*1 -> 0 | I35: =I34*1.75 -> 0 | J35: =J34*2 -> 0 | K35: =K34*0.3 -> 0 | L35: =SUM(L3:L33) -> 0
A37: APONTAMENTO DE HORAS
A38: Nome
A39: COLOQUE SEU NOME COMPLETO AQUI!
A40: Empresa | G40: Cliente
A41: GTI Solution
A42: Projeto(s) | G42: Data Inicial | I42: Data Final
G43: 44562 | I43: 44592
A45: Legenda
B46: Sábado / Domingo
B47: Feriado

Sheet Fevereiro_22
A1: Dia | B1: Dia da Semana | C1: Entrada | D1: Almoço | E1: Retorno | F1: Saída | G1: Total Horas | H1: Horas Normais | I1: Horas 75% | J1: Horas 100% | K1: Adic. Noturno | M1: Descrição das Atividades
L2: Convert
A3: 44593 | B3: =A3 -> 44593 | C3: 0 | D3: 0 | E3: 0 | F3: 0 | G3: =IF(A3=" "," ",(D3-C3)+(F3-E3)) -> 0 | H3: {=IF(OR(WEEKDAY(A3)=1,WEEKDAY(A3)=7,'.'!A:A=A3),TIME(0,0,0),IF((G3*24)>8,TIME(8,0,0),G3))} -> 0 | I3: {=IF(OR(WEEKDAY(A3)=1,WEEKDAY(A3)=7,'.'!A:A=A3),TIME(0,0,0),IF((G3*24)>10,TIME(2,0,0),IF((G3*24)<=8,TIME(0,0,0),G3-TIME(8,0,0))))} -> 0 | J3: {=IF(OR(WEEKDAY(A3)=1,WEEKDAY(A3)=7,'.'!A:A=A3),G3,IF((G3*24)>10,IF((G3*24)<=10,TIME(0,0,0),G3-TIME(10,0,0)),TIME(0,0,0)))} -> 0 | K3: =IF((G3*24)=0,TIME(0,0,0),IF((C3*24)<6,TIME(6-(C3*24),0,0),TIME(0,0,0))+IF((F3*24)>22,F3-TIME(22,0,0),TIME(0,0,0))) -> 0 | L3: =IF(A3=" "," ",((H3*24)+(I3*24*1.75)+(J3*24*2)+(K3*24*0.3))) -> 0
A4: 44594 | B4: =A4 -> 44594 | C4: 0 | D4: 0 | E4: 0 | F4: 0 | G4: =IF(A4=" "," ",(D4-C4)+(F4-E4)) -> 0 | H4: {=IF(OR(WEEKDAY(A4)=1,WEEKDAY(A4)=7,'.'!A:A=A4),TIME(0,0,0),IF((G4*24)>8,TIME(8,0,0),G4))} -> 0 | I4: {=IF(OR(WEEKDAY(A4)=1,WEEKDAY(A4)=7,'.'!A:A=A4),TIME(0,0,0),IF((G4*24)>10,TIME(2,0,0),IF((G4*24)<=8,TIME(0,0,0),G4-TIME(8,0,0))))} -> 0 | J4: {=IF(OR(WEEKDAY(A4)=1,WEEKDAY(A4)=7,'.'!A:A=A4),G4,IF((G4*24)>10,IF((G4*24)<=10,TIME(0,0,0),G4-TIME(10,0,0)),TIME(0,0,0)))} -> 0 | K4: =IF((G4*24)=0,TIME(0,0,0),IF((C4*24)<6,TIME(6-(C4*24),0,0),TIME(0,0,0))+IF((F4*24)>22,F4-TIME(22,0,0),TIME(0,0,0))) -> 0 | L4: =IF(A4=" "," ",((H4*24)+(I4*24*1.75)+(J4*24*2)+(K4*24*0.3))) -> 0
A5: 44595 | B5: =A5 -> 44595 | C5: 0 | D5: 0 | E5: 0 | F5: 0 | G5: =IF(A5=" "," ",(D5-C5)+(F5-E5)) -> 0 | H5: {=IF(OR(WEEKDAY(A5)=1,WEEKDAY(A5)=7,'.'!A:A=A5),TIME(0,0,0),IF((G5*24)>8,TIME(8,0,0),G5))} -> 0 | I5: {=IF(OR(WEEKDAY(A5)=1,WEEKDAY(A5)=7,'.'!A:A=A5),TIME(0,0,0),IF((G5*24)>10,TIME(2,0,0),IF((G5*24)<=8,TIME(0,0,0),G5-TIME(8,0,0))))} -> 0 | J5: {=IF(OR(WEEKDAY(A5)=1,WEEKDAY(A5)=7,'.'!A:A=A5),G5,IF((G5*24)>10,IF((G5*24)<=10,TIME(0,0,0),G5-TIME(10,0,0)),TIME(0,0,0)))} -> 0 | K5: =IF((G5*24)=0,TIME(0,0,0),IF((C5*24)<6,TIME(6-(C5*24),0,0),TIME(0,0,0))+IF((F5*24)>22,F5-TIME(22,0,0),TIME(0,0,0))) -> 0 | L5: =IF(A5=" "," ",((H5*24)+(I5*24*1.75)+(J5*24*2)+(K5*24*0.3))) -> 0
A6: 44596 | B6: =A6 -> 44596 | C6: 0 | D6: 0 | E6: 0 | F6: 0 | G6: =IF(A6=" "," ",(D6-C6)+(F6-E6)) -> 0 | H6: {=IF(OR(WEEKDAY(A6)=1,WEEKDAY(A6)=7,'.'!A:A=A6),TIME(0,0,0),IF((G6*24)>8,TIME(8,0,0),G6))} -> 0 | I6: {=IF(OR(WEEKDAY(A6)=1,WEEKDAY(A6)=7,'.'!A:A=A6),TIME(0,0,0),IF((G6*24)>10,TIME(2,0,0),IF((G6*24)<=8,TIME(0,0,0),G6-TIME(8,0,0))))} -> 0 | J6: {=IF(OR(WEEKDAY(A6)=1,WEEKDAY(A6)=7,'.'!A:A=A6),G6,IF((G6*24)>10,IF((G6*24)<=10,TIME(0,0,0),G6-TIME(10,0,0)),TIME(0,0,0)))} -> 0 | K6: =IF((G6*24)=0,TIME(0,0,0),IF((C6*24)<6,TIME(6-(C6*24),0,0),TIME(0,0,0))+IF((F6*24)>22,F6-TIME(22,0,0),TIME(0,0,0))) -> 0 | L6: =IF(A6=" "," ",((H6*24)+(I6*24*1.75)+(J6*24*2)+(K6*24*0.3))) -> 0
A7: 44597 | B7: =A7 -> 44597 | C7: 0 | D7: 0 | E7: 0 | F7: 0 | G7: =IF(A7=" "," ",(D7-C7)+(F7-E7)) -> 0 | H7: {=IF(OR(WEEKDAY(A7)=1,WEEKDAY(A7)=7,'.'!A:A=A7),TIME(0,0,0),IF((G7*24)>8,TIME(8,0,0),G7))} -> 0 | I7: {=IF(OR(WEEKDAY(A7)=1,WEEKDAY(A7)=7,'.'!A:A=A7),TIME(0,0,0),IF((G7*24)>10,TIME(2,0,0),IF((G7*24)<=8,TIME(0,0,0),G7-TIME(8,0,0))))} -> 0 | J7: {=IF(OR(WEEKDAY(A7)=1,WEEKDAY(A7)=7,'.'!A:A=A7),G7,IF((G7*24)>10,IF((G7*24)<=10,TIME(0,0,0),G7-TIME(10,0,0)),TIME(0,0,0)))} -> 0 | K7: =IF((G7*24)=0,TIME(0,0,0),IF((C7*24)<6,TIME(6-(C7*24),0,0),TIME(0,0,0))+IF((F7*24)>22,F7-TIME(22,0,0),TIME(0,0,0))) -> 0 | L7: =IF(A7=" "," ",((H7*24)+(I7*24*1.75)+(J7*24*2)+(K7*24*0.3))) -> 0
A8: 44598 | B8: =A8 -> 44598 | C8: 0 | D8: 0 | E8: 0 | F8: 0 | G8: =IF(A8=" "," ",(D8-C8)+(F8-E8)) -> 0 | H8: {=IF(OR(WEEKDAY(A8)=1,WEEKDAY(A8)=7,'.'!A:A=A8),TIME(0,0,0),IF((G8*24)>8,TIME(8,0,0),G8))} -> 0 | I8: {=IF(OR(WEEKDAY(A8)=1,WEEKDAY(A8)=7,'.'!A:A=A8),TIME(0,0,0),IF((G8*24)>10,TIME(2,0,0),IF((G8*24)<=8,TIME(0,0,0),G8-TIME(8,0,0))))} -> 0 | J8: {=IF(OR(WEEKDAY(A8)=1,WEEKDAY(A8)=7,'.'!A:A=A8),G8,IF((G8*24)>10,IF((G8*24)<=10,TIME(0,0,0),G8-TIME(10,0,0)),TIME(0,0,0)))} -> 0 | K8: =IF((G8*24)=0,TIME(0,0,0),IF((C8*24)<6,TIME(6-(C8*24),0,0),TIME(0,0,0))+IF((F8*24)>22,F8-TIME(22,0,0),TIME(0,0,0))) -> 0 | L8: =IF(A8=" "," ",((H8*24)+(I8*24*1.75)+(J8*24*2)+(K8*24*0.3))) -> 0
A9: 44599 | B9: =A9 -> 44599 | C9: 0 | D9: 0 | E9: 0 | F9: 0 | G9: =IF(A9=" "," ",(D9-C9)+(F9-E9)) -> 0 | H9: {=IF(OR(WEEKDAY(A9)=1,WEEKDAY(A9)=7,'.'!A:A=A9),TIME(0,0,0),IF((G9*24)>8,TIME(8,0,0),G9))} -> 0 | I9: {=IF(OR(WEEKDAY(A9)=1,WEEKDAY(A9)=7,'.'!A:A=A9),TIME(0,0,0),IF((G9*24)>10,TIME(2,0,0),IF((G9*24)<=8,TIME(0,0,0),G9-TIME(8,0,0))))} -> 0 | J9: {=IF(OR(WEEKDAY(A9)=1,WEEKDAY(A9)=7,'.'!A:A=A9),G9,IF((G9*24)>10,IF((G9*24)<=10,TIME(0,0,0),G9-TIME(10,0,0)),TIME(0,0,0)))} -> 0 | K9: =IF((G9*24)=0,TIME(0,0,0),IF((C9*24)<6,TIME(6-(C9*24),0,0),TIME(0,0,0))+IF((F9*24)>22,F9-TIME(22,0,0),TIME(0,0,0))) -> 0 | L9: =IF(A9=" "," ",((H9*24)+(I9*24*1.75)+(J9*24*2)+(K9*24*0.3))) -> 0
A10: 44600 | B10: =A10 -> 44600 | C10: 0 | D10: 0 | E10: 0 | F10: 0 | G10: =IF(A10=" "," ",(D10-C10)+(F10-E10)) -> 0 | H10: {=IF(OR(WEEKDAY(A10)=1,WEEKDAY(A10)=7,'.'!A:A=A10),TIME(0,0,0),IF((G10*24)>8,TIME(8,0,0),G10))} -> 0 | I10: {=IF(OR(WEEKDAY(A10)=1,WEEKDAY(A10)=7,'.'!A:A=A10),TIME(0,0,0),IF((G10*24)>10,TIME(2,0,0),IF((G10*24)<=8,TIME(0,0,0),G10-TIME(8,0,0))))} -> 0 | J10: {=IF(OR(WEEKDAY(A10)=1,WEEKDAY(A10)=7,'.'!A:A=A10),G10,IF((G10*24)>10,IF((G10*24)<=10,TIME(0,0,0),G10-TIME(10,0,0)),TIME(0,0,0)))} -> 0 | K10: =IF((G10*24)=0,TIME(0,0,0),IF((C10*24)<6,TIME(6-(C10*24),0,0),TIME(0,0,0))+IF((F10*24)>22,F10-TIME(22,0,0),TIME(0,0,0))) -> 0 | L10: =IF(A10=" "," ",((H10*24)+(I10*24*1.75)+(J10*24*2)+(K10*24*0.3))) -> 0
A11: 44601 | B11: =A11 -> 44601 | C11: 0 | D11: 0 | E11: 0 | F11: 0 | G11: =IF(A11=" "," ",(D11-C11)+(F11-E11)) -> 0 | H11: {=IF(OR(WEEKDAY(A11)=1,WEEKDAY(A11)=7,'.'!A:A=A11),TIME(0,0,0),IF((G11*24)>8,TIME(8,0,0),G11))} -> 0 | I11: {=IF(OR(WEEKDAY(A11)=1,WEEKDAY(A11)=7,'.'!A:A=A11),TIME(0,0,0),IF((G11*24)>10,TIME(2,0,0),IF((G11*24)<=8,TIME(0,0,0),G11-TIME(8,0,0))))} -> 0 | J11: {=IF(OR(WEEKDAY(A11)=1,WEEKDAY(A11)=7,'.'!A:A=A11),G11,IF((G11*24)>10,IF((G11*24)<=10,TIME(0,0,0),G11-TIME(10,0,0)),TIME(0,0,0)))} -> 0 | K11: =IF((G11*24)=0,TIME(0,0,0),IF((C11*24)<6,TIME(6-(C11*24),0,0),TIME(0,0,0))+IF((F11*24)>22,F11-TIME(22,0,0),TIME(0,0,0))) -> 0 | L11: =IF(A11=" "," ",((H11*24)+(I11*24*1.75)+(J11*24*2)+(K11*24*0.3))) -> 0
A12: 44602 | B12: =A12 -> 44602 | C12: 0 | D12: 0 | E12: 0 | F12: 0 | G12: =IF(A12=" "," ",(D12-C12)+(F12-E12)) -> 0 | H12: {=IF(OR(WEEKDAY(A12)=1,WEEKDAY(A12)=7,'.'!A:A=A12),TIME(0,0,0),IF((G12*24)>8,TIME(8,0,0),G12))} -> 0 | I12: {=IF(OR(WEEKDAY(A12)=1,WEEKDAY(A12)=7,'.'!A:A=A12),TIME(0,0,0),IF((G12*24)>10,TIME(2,0,0),IF((G12*24)<=8,TIME(0,0,0),G12-TIME(8,0,0))))} -> 0 | J12: {=IF(OR(WEEKDAY(A12)=1,WEEKDAY(A12)=7,'.'!A:A=A12),G12,IF((G12*24)>10,IF((G12*24)<=10,TIME(0,0,0),G12-TIME(10,0,0)),TIME(0,0,0)))} -> 0 | K12: =IF((G12*24)=0,TIME(0,0,0),IF((C12*24)<6,TIME(6-(C12*24),0,0),TIME(0,0,0))+IF((F12*24)>22,F12-TIME(22,0,0),TIME(0,0,0))) -> 0 | L12: =IF(A12=" "," ",((H12*24)+(I12*24*1.75)+(J12*24*2)+(K12*24*0.3))) -> 0
A13: 44603 | B13: =A13 -> 44603 | C13: 0 | D13: 0 | E13: 0 | F13: 0 | G13: =IF(A13=" "," ",(D13-C13)+(F13-E13)) -> 0 | H13: {=IF(OR(WEEKDAY(A13)=1,WEEKDAY(A13)=7,'.'!A:A=A13),TIME(0,0,0),IF((G13*24)>8,TIME(8,0,0),G13))} -> 0 | I13: {=IF(OR(WEEKDAY(A13)=1,WEEKDAY(A13)=7,'.'!A:A=A13),TIME(0,0,0),IF((G13*24)>10,TIME(2,0,0),IF((G13*24)<=8,TIME(0,0,0),G13-TIME(8,0,0))))} -> 0 | J13: {=IF(OR(WEEKDAY(A13)=1,WEEKDAY(A13)=7,'.'!A:A=A13),G13,IF((G13*24)>10,IF((G13*24)<=10,TIME(0,0,0),G13-TIME(10,0,0)),TIME(0,0,0)))} -> 0 | K13: =IF((G13*24)=0,TIME(0,0,0),IF((C13*24)<6,TIME(6-(C13*24),0,0),TIME(0,0,0))+IF((F13*24)>22,F13-TIME(22,0,0),TIME(0,0,0))) -> 0 | L13: =IF(A13=" "," ",((H13*24)+(I13*24*1.75)+(J13*24*2)+(K13*24*0.3))) -> 0
A14: 44604 | B14: =A14 -> 44604 | C14: 0 | D14: 0 | E14: 0 | F14: 0 | G14: =IF(A14=" "," ",(D14-C14)+(F14-E14)) -> 0 | H14: {=IF(OR(WEEKDAY(A14)=1,WEEKDAY(A14)=7,'.'!A:A=A14),TIME(0,0,0),IF((G14*24)>8,TIME(8,0,0),G14))} -> 0 | I14: {=IF(OR(WEEKDAY(A14)=1,WEEKDAY(A14)=7,'.'!A:A=A14),TIME(0,0,0),IF((G14*24)>10,TIME(2,0,0),IF((G14*24)<=8,TIME(0,0,0),G14-TIME(8,0,0))))} -> 0 | J14: {=IF(OR(WEEKDAY(A14)=1,WEEKDAY(A14)=7,'.'!A:A=A14),G14,IF((G14*24)>10,IF((G14*24)<=10,TIME(0,0,0),G14-TIME(10,0,0)),TIME(0,0,0)))} -> 0 | K14: =IF((G14*24)=0,TIME(0,0,0),IF((C14*24)<6,TIME(6-(C14*24),0,0),TIME(0,0,0))+IF((F14*24)>22,F14-TIME(22,0,0),TIME(0,0,0))) -> 0 | L14: =IF(A14=" "," ",((H14*24)+(I14*24*1.75)+(J14*24*2)+(K14*24*0.3))) -> 0
... A30: 44620 | B30: =A30 -> 44620 | C30: 0 | D30: 0 | E30: 0 | F30: 0 | G30: =IF(A30=" "," ",(D30-C30)+(F30-E30)) -> 0 | H30: {=IF(OR(WEEKDAY(A30)=1,WEEKDAY(A30)=7,'.'!A:A=A30),TIME(0,0,0),IF((G30*24)>8,TIME(8,0,0),G30))} -> 0 | I30: {=IF(OR(WEEKDAY(A30)=1,WEEKDAY(A30)=7,'.'!A:A=A30),TIME(0,0,0),IF((G30*24)>10,TIME(2,0,0),IF((G30*24)<=8,TIME(0,0,0),G30-TIME(8,0,0))))} -> 0 | J30: {=IF(OR(WEEKDAY(A30)=1,WEEKDAY(A30)=7,'.'!A:A=A30),G30,IF((G30*24)>10,IF((G30*24)<=10,TIME(0,0,0),G30-TIME(10,0,0)),TIME(0,0,0)))} -> 0 | K30: =IF((G30*24)=0,TIME(0,0,0),IF((C30*24)<6,TIME(6-(C30*24),0,0),TIME(0,0,0))+IF((F30*24)>22,F30-TIME(22,0,0),TIME(0,0,0))) -> 0 | L30: =IF(A30=" "," ",((H30*24)+(I30*24*1.75)+(J30*24*2)+(K30*24*0.3))) -> 0
A32: Totais | G32: =SUM(G3:G31)*24 -> 0 | H32: =SUM(H3:H31)*24 -> 0 | I32: =SUM(I3:I31)*24 -> 0 | J32: =SUM(J3:J31)*24 -> 0 | K32: =SUM(K3:K31)*24 -> 0
A33: Total de horas carregadas com adicionais | H33: =H32*1 -> 0 | I33: =I32*1.75 -> 0 | J33: =J32*2 -> 0 | K33: =K32*0.3 -> 0 | L33: =SUM(L3:L31) -> 0
A35: APONTAMENTO DE HORAS
A36: Nome
A37: =Janeiro_22!A39 -> COLOQUE SEU NOME COMPLETO AQUI!
A38: Empresa | G38: Cliente
A39: GTI Solution
A40: Projeto(s) | G40: Data Inicial | I40: Data Final
G41: 44593 | I41: 44620
A43: Legenda
B44: Sábado / Domingo
B45: Feriado

Sheet Março_22
A1: Dia | B1: Dia da Semana | C1: Entrada | D1: Almoço | E1: Retorno | F1: Saída | G1: Total Horas | H1: Horas Normais | I1: Horas 75% | J1: Horas 100% | K1: Adic. Noturno | L1: Convert | M1: Descrição das Atividades
A3: 44621 | B3: =A3 -> 44621 | C3: 0 | D3: 0 | E3: 0 | F3: 0 | G3: =IF(A3=" "," ",(D3-C3)+(F3-E3)) -> 0 | H3: {=IF(OR(WEEKDAY(A3)=1,WEEKDAY(A3)=7,'.'!A:A=A3),TIME(0,0,0),IF((G3*24)>8,TIME(8,0,0),G3))} -> 0 | I3: {=IF(OR(WEEKDAY(A3)=1,WEEKDAY(A3)=7,'.'!A:A=A3),TIME(0,0,0),IF((G3*24)>10,TIME(2,0,0),IF((G3*24)<=8,TIME(0,0,0),G3-TIME(8,0,0))))} -> 0 | J3: {=IF(OR(WEEKDAY(A3)=1,WEEKDAY(A3)=7,'.'!A:A=A3),G3,IF((G3*24)>10,IF((G3*24)<=10,TIME(0,0,0),G3-TIME(10,0,0)),TIME(0,0,0)))} -> 0 | K3: =IF((G3*24)=0,TIME(0,0,0),IF((C3*24)<6,TIME(6-(C3*24),0,0),TIME(0,0,0))+IF((F3*24)>22,F3-TIME(22,0,0),TIME(0,0,0))) -> 0 | L3: =IF(A3=" "," ",((H3*24)+(I3*24*1.75)+(J3*24*2)+(K3*24*0.3))) -> 0 | M3: Carnaval
A4: 44622 | B4: =A4 -> 44622 | C4: 0 | D4: 0 | E4: 0 | F4: 0 | G4: =IF(A4=" "," ",(D4-C4)+(F4-E4)) -> 0 | H4: {=IF(OR(WEEKDAY(A4)=1,WEEKDAY(A4)=7,'.'!A:A=A4),TIME(0,0,0),IF((G4*24)>8,TIME(8,0,0),G4))} -> 0 | I4: {=IF(OR(WEEKDAY(A4)=1,WEEKDAY(A4)=7,'.'!A:A=A4),TIME(0,0,0),IF((G4*24)>10,TIME(2,0,0),IF((G4*24)<=8,TIME(0,0,0),G4-TIME(8,0,0))))} -> 0 | J4: {=IF(OR(WEEKDAY(A4)=1,WEEKDAY(A4)=7,'.'!A:A=A4),G4,IF((G4*24)>10,IF((G4*24)<=10,TIME(0,0,0),G4-TIME(10,0,0)),TIME(0,0,0)))} -> 0 | K4: =IF((G4*24)=0,TIME(0,0,0),IF((C4*24)<6,TIME(6-(C4*24),0,0),TIME(0,0,0))+IF((F4*24)>22,F4-TIME(22,0,0),TIME(0,0,0))) -> 0 | L4: =IF(A4=" "," ",((H4*24)+(I4*24*1.75)+(J4*24*2)+(K4*24*0.3))) -> 0
A5: 44623 | B5: =A5 -> 44623 | C5: 0 | D5: 0 | E5: 0 | F5: 0 | G5: =IF(A5=" "," ",(D5-C5)+(F5-E5)) -> 0 | H5: {=IF(OR(WEEKDAY(A5)=1,WEEKDAY(A5)=7,'.'!A:A=A5),TIME(0,0,0),IF((G5*24)>8,TIME(8,0,0),G5))} -> 0 | I5: {=IF(OR(WEEKDAY(A5)=1,WEEKDAY(A5)=7,'.'!A:A=A5),TIME(0,0,0),IF((G5*24)>10,TIME(2,0,0),IF((G5*24)<=8,TIME(0,0,0),G5-TIME(8,0,0))))} -> 0 | J5: {=IF(OR(WEEKDAY(A5)=1,WEEKDAY(A5)=7,'.'!A:A=A5),G5,IF((G5*24)>10,IF((G5*24)<=10,TIME(0,0,0),G5-TIME(10,0,0)),TIME(0,0,0)))} -> 0 | K5: =IF((G5*24)=0,TIME(0,0,0),IF((C5*24)<6,TIME(6-(C5*24),0,0),TIME(0,0,0))+IF((F5*24)>22,F5-TIME(22,0,0),TIME(0,0,0))) -> 0 | L5: =IF(A5=" "," ",((H5*24)+(I5*24*1.75)+(J5*24*2)+(K5*24*0.3))) -> 0
A6: 44624 | B6: =A6 -> 44624 | C6: 0 | D6: 0 | E6: 0 | F6: 0 | G6: =IF(A6=" "," ",(D6-C6)+(F6-E6)) -> 0 | H6: {=IF(OR(WEEKDAY(A6)=1,WEEKDAY(A6)=7,'.'!A:A=A6),TIME(0,0,0),IF((G6*24)>8,TIME(8,0,0),G6))} -> 0 | I6: {=IF(OR(WEEKDAY(A6)=1,WEEKDAY(A6)=7,'.'!A:A=A6),TIME(0,0,0),IF((G6*24)>10,TIME(2,0,0),IF((G6*24)<=8,TIME(0,0,0),G6-TIME(8,0,0))))} -> 0 | J6: {=IF(OR(WEEKDAY(A6)=1,WEEKDAY(A6)=7,'.'!A:A=A6),G6,IF((G6*24)>10,IF((G6*24)<=10,TIME(0,0,0),G6-TIME(10,0,0)),TIME(0,0,0)))} -> 0 | K6: =IF((G6*24)=0,TIME(0,0,0),IF((C6*24)<6,TIME(6-(C6*24),0,0),TIME(0,0,0))+IF((F6*24)>22,F6-TIME(22,0,0),TIME(0,0,0))) -> 0 | L6: =IF(A6=" "," ",((H6*24)+(I6*24*1.75)+(J6*24*2)+(K6*24*0.3))) -> 0
A7: 44625 | B7: =A7 -> 44625 | C7: 0 | D7: 0 | E7: 0 | F7: 0 | G7: =IF(A7=" "," ",(D7-C7)+(F7-E7)) -> 0 | H7: {=IF(OR(WEEKDAY(A7)=1,WEEKDAY(A7)=7,'.'!A:A=A7),TIME(0,0,0),IF((G7*24)>8,TIME(8,0,0),G7))} -> 0 | I7: {=IF(OR(WEEKDAY(A7)=1,WEEKDAY(A7)=7,'.'!A:A=A7),TIME(0,0,0),IF((G7*24)>10,TIME(2,0,0),IF((G7*24)<=8,TIME(0,0,0),G7-TIME(8,0,0))))} -> 0 | J7: {=IF(OR(WEEKDAY(A7)=1,WEEKDAY(A7)=7,'.'!A:A=A7),G7,IF((G7*24)>10,IF((G7*24)<=10,TIME(0,0,0),G7-TIME(10,0,0)),TIME(0,0,0)))} -> 0 | K7: =IF((G7*24)=0,TIME(0,0,0),IF((C7*24)<6,TIME(6-(C7*24),0,0),TIME(0,0,0))+IF((F7*24)>22,F7-TIME(22,0,0),TIME(0,0,0))) -> 0 | L7: =IF(A7=" "," ",((H7*24)+(I7*24*1.75)+(J7*24*2)+(K7*24*0.3))) -> 0
A8: 44626 | B8: =A8 -> 44626 | C8: 0 | D8: 0 | E8: 0 | F8: 0 | G8: =IF(A8=" "," ",(D8-C8)+(F8-E8)) -> 0 | H8: {=IF(OR(WEEKDAY(A8)=1,WEEKDAY(A8)=7,'.'!A:A=A8),TIME(0,0,0),IF((G8*24)>8,TIME(8,0,0),G8))} -> 0 | I8: {=IF(OR(WEEKDAY(A8)=1,WEEKDAY(A8)=7,'.'!A:A=A8),TIME(0,0,0),IF((G8*24)>10,TIME(2,0,0),IF((G8*24)<=8,TIME(0,0,0),G8-TIME(8,0,0))))} -> 0 | J8: {=IF(OR(WEEKDAY(A8)=1,WEEKDAY(A8)=7,'.'!A:A=A8),G8,IF((G8*24)>10,IF((G8*24)<=10,TIME(0,0,0),G8-TIME(10,0,0)),TIME(0,0,0)))} -> 0 | K8: =IF((G8*24)=0,TIME(0,0,0),IF((C8*24)<6,TIME(6-(C8*24),0,0),TIME(0,0,0))+IF((F8*24)>22,F8-TIME(22,0,0),TIME(0,0,0))) -> 0 | L8: =IF(A8=" "," ",((H8*24)+(I8*24*1.75)+(J8*24*2)+(K8*24*0.3))) -> 0
A9: 44627 | B9: =A9 -> 44627 | C9: 0 | D9: 0 | E9: 0 | F9: 0 | G9: =IF(A9=" "," ",(D9-C9)+(F9-E9)) -> 0 | H9: {=IF(OR(WEEKDAY(A9)=1,WEEKDAY(A9)=7,'.'!A:A=A9),TIME(0,0,0),IF((G9*24)>8,TIME(8,0,0),G9))} -> 0 | I9: {=IF(OR(WEEKDAY(A9)=1,WEEKDAY(A9)=7,'.'!A:A=A9),TIME(0,0,0),IF((G9*24)>10,TIME(2,0,0),IF((G9*24)<=8,TIME(0,0,0),G9-TIME(8,0,0))))} -> 0 | J9: {=IF(OR(WEEKDAY(A9)=1,WEEKDAY(A9)=7,'.'!A:A=A9),G9,IF((G9*24)>10,IF((G9*24)<=10,TIME(0,0,0),G9-TIME(10,0,0)),TIME(0,0,0)))} -> 0 | K9: =IF((G9*24)=0,TIME(0,0,0),IF((C9*24)<6,TIME(6-(C9*24),0,0),TIME(0,0,0))+IF((F9*24)>22,F9-TIME(22,0,0),TIME(0,0,0))) -> 0 | L9: =IF(A9=" "," ",((H9*24)+(I9*24*1.75)+(J9*24*2)+(K9*24*0.3))) -> 0
A10: 44628 | B10: =A10 -> 44628 | C10: 0 | D10: 0 | E10: 0 | F10: 0 | G10: =IF(A10=" "," ",(D10-C10)+(F10-E10)) -> 0 | H10: {=IF(OR(WEEKDAY(A10)=1,WEEKDAY(A10)=7,'.'!A:A=A10),TIME(0,0,0),IF((G10*24)>8,TIME(8,0,0),G10))} -> 0 | I10: {=IF(OR(WEEKDAY(A10)=1,WEEKDAY(A10)=7,'.'!A:A=A10),TIME(0,0,0),IF((G10*24)>10,TIME(2,0,0),IF((G10*24)<=8,TIME(0,0,0),G10-TIME(8,0,0))))} -> 0 | J10: {=IF(OR(WEEKDAY(A10)=1,WEEKDAY(A10)=7,'.'!A:A=A10),G10,IF((G10*24)>10,IF((G10*24)<=10,TIME(0,0,0),G10-TIME(10,0,0)),TIME(0,0,0)))} -> 0 | K10: =IF((G10*24)=0,TIME(0,0,0),IF((C10*24)<6,TIME(6-(C10*24),0,0),TIME(0,0,0))+IF((F10*24)>22,F10-TIME(22,0,0),TIME(0,0,0))) -> 0 | L10: =IF(A10=" "," ",((H10*24)+(I10*24*1.75)+(J10*24*2)+(K10*24*0.3))) -> 0
A11: 44629 | B11: =A11 -> 44629 | C11: 0 | D11: 0 | E11: 0 | F11: 0 | G11: =IF(A11=" "," ",(D11-C11)+(F11-E11)) -> 0 | H11: {=IF(OR(WEEKDAY(A11)=1,WEEKDAY(A11)=7,'.'!A:A=A11),TIME(0,0,0),IF((G11*24)>8,TIME(8,0,0),G11))} -> 0 | I11: {=IF(OR(WEEKDAY(A11)=1,WEEKDAY(A11)=7,'.'!A:A=A11),TIME(0,0,0),IF((G11*24)>10,TIME(2,0,0),IF((G11*24)<=8,TIME(0,0,0),G11-TIME(8,0,0))))} -> 0 | J11: {=IF(OR(WEEKDAY(A11)=1,WEEKDAY(A11)=7,'.'!A:A=A11),G11,IF((G11*24)>10,IF((G11*24)<=10,TIME(0,0,0),G11-TIME(10,0,0)),TIME(0,0,0)))} -> 0 | K11: =IF((G11*24)=0,TIME(0,0,0),IF((C11*24)<6,TIME(6-(C11*24),0,0),TIME(0,0,0))+IF((F11*24)>22,F11-TIME(22,0,0),TIME(0,0,0))) -> 0 | L11: =IF(A11=" "," ",((H11*24)+(I11*24*1.75)+(J11*24*2)+(K11*24*0.3))) -> 0
A12: 44630 | B12: =A12 -> 44630 | C12: 0 | D12: 0 | E12: 0 | F12: 0 | G12: =IF(A12=" "," ",(D12-C12)+(F12-E12)) -> 0 | H12: {=IF(OR(WEEKDAY(A12)=1,WEEKDAY(A12)=7,'.'!A:A=A12),TIME(0,0,0),IF((G12*24)>8,TIME(8,0,0),G12))} -> 0 | I12: {=IF(OR(WEEKDAY(A12)=1,WEEKDAY(A12)=7,'.'!A:A=A12),TIME(0,0,0),IF((G12*24)>10,TIME(2,0,0),IF((G12*24)<=8,TIME(0,0,0),G12-TIME(8,0,0))))} -> 0 | J12: {=IF(OR(WEEKDAY(A12)=1,WEEKDAY(A12)=7,'.'!A:A=A12),G12,IF((G12*24)>10,IF((G12*24)<=10,TIME(0,0,0),G12-TIME(10,0,0)),TIME(0,0,0)))} -> 0 | K12: =IF((G12*24)=0,TIME(0,0,0),IF((C12*24)<6,TIME(6-(C12*24),0,0),TIME(0,0,0))+IF((F12*24)>22,F12-TIME(22,0,0),TIME(0,0,0))) -> 0 | L12: =IF(A12=" "," ",((H12*24)+(I12*24*1.75)+(J12*24*2)+(K12*24*0.3))) -> 0
A13: 44631 | B13: =A13 -> 44631 | C13: 0 | D13: 0 | E13: 0 | F13: 0 | G13: =IF(A13=" "," ",(D13-C13)+(F13-E13)) -> 0 | H13: {=IF(OR(WEEKDAY(A13)=1,WEEKDAY(A13)=7,'.'!A:A=A13),TIME(0,0,0),IF((G13*24)>8,TIME(8,0,0),G13))} -> 0 | I13: {=IF(OR(WEEKDAY(A13)=1,WEEKDAY(A13)=7,'.'!A:A=A13),TIME(0,0,0),IF((G13*24)>10,TIME(2,0,0),IF((G13*24)<=8,TIME(0,0,0),G13-TIME(8,0,0))))} -> 0 | J13: {=IF(OR(WEEKDAY(A13)=1,WEEKDAY(A13)=7,'.'!A:A=A13),G13,IF((G13*24)>10,IF((G13*24)<=10,TIME(0,0,0),G13-TIME(10,0,0)),TIME(0,0,0)))} -> 0 | K13: =IF((G13*24)=0,TIME(0,0,0),IF((C13*24)<6,TIME(6-(C13*24),0,0),TIME(0,0,0))+IF((F13*24)>22,F13-TIME(22,0,0),TIME(0,0,0))) -> 0 | L13: =IF(A13=" "," ",((H13*24)+(I13*24*1.75)+(J13*24*2)+(K13*24*0.3))) -> 0
A14: 44632 | B14: =A14 -> 44632 | C14: 0 | D14: 0 | E14: 0 | F14: 0 | G14: =IF(A14=" "," ",(D14-C14)+(F14-E14)) -> 0 | H14: {=IF(OR(WEEKDAY(A14)=1,WEEKDAY(A14)=7,'.'!A:A=A14),TIME(0,0,0),IF((G14*24)>8,TIME(8,0,0),G14))} -> 0 | I14: {=IF(OR(WEEKDAY(A14)=1,WEEKDAY(A14)=7,'.'!A:A=A14),TIME(0,0,0),IF((G14*24)>10,TIME(2,0,0),IF((G14*24)<=8,TIME(0,0,0),G14-TIME(8,0,0))))} -> 0 | J14: {=IF(OR(WEEKDAY(A14)=1,WEEKDAY(A14)=7,'.'!A:A=A14),G14,IF((G14*24)>10,IF((G14*24)<=10,TIME(0,0,0),G14-TIME(10,0,0)),TIME(0,0,0)))} -> 0 | K14: =IF((G14*24)=0,TIME(0,0,0),IF((C14*24)<6,TIME(6-(C14*24),0,0),TIME(0,0,0))+IF((F14*24)>22,F14-TIME(22,0,0),TIME(0,0,0))) -> 0 | L14: =IF(A14=" "," ",((H14*24)+(I14*24*1.75)+(J14*24*2)+(K14*24*0.3))) -> 0
A15: 44633 | B15: =A15 -> 44633 | C15: 0 | D15: 0 | E15: 0 | F15: 0 | G15: =IF(A15=" "," ",(D15-C15)+(F15-E15)) -> 0 | H15: {=IF(OR(WEEKDAY(A15)=1,WEEKDAY(A15)=7,'.'!A:A=A15),TIME(0,0,0),IF((G15*24)>8,TIME(8,0,0),G15))} -> 0 | I15: {=IF(OR(WEEKDAY(A15)=1,WEEKDAY(A15)=7,'.'!A:A=A15),TIME(0,0,0),IF((G15*24)>10,TIME(2,0,0),IF((G15*24)<=8,TIME(0,0,0),G15-TIME(8,0,0))))} -> 0 | J15: {=IF(OR(WEEKDAY(A15)=1,WEEKDAY(A15)=7,'.'!A:A=A15),G15,IF((G15*24)>10,IF((G15*24)<=10,TIME(0,0,0),G15-TIME(10,0,0)),TIME(0,0,0)))} -> 0 | K15: =IF((G15*24)=0,TIME(0,0,0),IF((C15*24)<6,TIME(6-(C15*24),0,0),TIME(0,0,0))+IF((F15*24)>22,F15-TIME(22,0,0),TIME(0,0,0))) -> 0 | L15: =IF(A15=" "," ",((H15*24)+(I15*24*1.75)+(J15*24*2)+(K15*24*0.3))) -> 0
... A33: 44651 | B33: =A33 -> 44651 | C33: 0 | D33: 0 | E33: 0 | F33: 0 | G33: =IF(A33=" "," ",(D33-C33)+(F33-E33)) -> 0 | H33: {=IF(OR(WEEKDAY(A33)=1,WEEKDAY(A33)=7,'.'!A:A=A33),TIME(0,0,0),IF((G33*24)>8,TIME(8,0,0),G33))} -> 0 | I33: {=IF(OR(WEEKDAY(A33)=1,WEEKDAY(A33)=7,'.'!A:A=A33),TIME(0,0,0),IF((G33*24)>10,TIME(2,0,0),IF((G33*24)<=8,TIME(0,0,0),G33-TIME(8,0,0))))} -> 0 | J33: {=IF(OR(WEEKDAY(A33)=1,WEEKDAY(A33)=7,'.'!A:A=A33),G33,IF((G33*24)>10,IF((G33*24)<=10,TIME(0,0,0),G33-TIME(10,0,0)),TIME(0,0,0)))} -> 0 | K33: =IF((G33*24)=0,TIME(0,0,0),IF((C33*24)<6,TIME(6-(C33*24),0,0),TIME(0,0,0))+IF((F33*24)>22,F33-TIME(22,0,0),TIME(0,0,0))) -> 0 | L33: =IF(A33=" "," ",((H33*24)+(I33*24*1.75)+(J33*24*2)+(K33*24*0.3))) -> 0
A34: Totais | G34: =SUM(G3:G33)*24 -> 0 | H34: =SUM(H3:H33)*24 -> 0 | I34: =SUM(I3:I33)*24 -> 0 | J34: =SUM(J3:J33)*24 -> 0 | K34: =SUM(K3:K33)*24 -> 0
A35: Total de horas carregadas com adicionais | H35: =H34*1 -> 0 | I35: =I34*1.75 -> 0 | J35: =J34*2 -> 0 | K35: =K34*0.3 -> 0 | L35: =SUM(L3:L33) -> 0
A37: APONTAMENTO DE HORAS
A38: Nome
A39: =Janeiro_22!A39 -> COLOQUE SEU NOME COMPLETO AQUI!
A40: Empresa | G40: Cliente
A41: GTI Solution
A42: Projeto(s) | G42: Data Inicial | I42: Data Final
G43: 44621 | I43: 44651
A45: Legenda
B46: Sábado / Domingo
B47: Feriado

Sheet Abril_22
A1: Dia | B1: Dia da Semana | C1: Entrada | D1: Almoço | E1: Retorno | F1: Saída | G1: Total Horas | H1: Horas Normais | I1: Horas 75% | J1: Horas 100% | K1: Adic. Noturno | L1: Convert | M1: Descrição das Atividades
A3: 44652 | B3: =A3 -> 44652 | C3: 0 | D3: 0 | E3: 0 | F3: 0 | G3: =IF(A3=" "," ",(D3-C3)+(F3-E3)) -> 0 | H3: {=IF(OR(WEEKDAY(A3)=1,WEEKDAY(A3)=7,'.'!A:A=A3),TIME(0,0,0),IF((G3*24)>8,TIME(8,0,0),G3))} -> 0 | I3: {=IF(OR(WEEKDAY(A3)=1,WEEKDAY(A3)=7,'.'!A:A=A3),TIME(0,0,0),IF((G3*24)>10,TIME(2,0,0),IF((G3*24)<=8,TIME(0,0,0),G3-TIME(8,0,0))))} -> 0 | J3: {=IF(OR(WEEKDAY(A3)=1,WEEKDAY(A3)=7,'.'!A:A=A3),G3,IF((G3*24)>10,IF((G3*24)<=10,TIME(0,0,0),G3-TIME(10,0,0)),TIME(0,0,0)))} -> 0 | K3: =IF((G3*24)=0,TIME(0,0,0),IF((C3*24)<6,TIME(6-(C3*24),0,0),TIME(0,0,0))+IF((F3*24)>22,F3-TIME(22,0,0),TIME(0,0,0))) -> 0 | L3: =IF(A3=" "," ",((H3*24)+(I3*24*1.75)+(J3*24*2)+(K3*24*0.3))) -> 0
A4: 44653 | B4: =A4 -> 44653 | C4: 0 | D4: 0 | E4: 0 | F4: 0 | G4: =IF(A4=" "," ",(D4-C4)+(F4-E4)) -> 0 | H4: {=IF(OR(WEEKDAY(A4)=1,WEEKDAY(A4)=7,'.'!A:A=A4),TIME(0,0,0),IF((G4*24)>8,TIME(8,0,0),G4))} -> 0 | I4: {=IF(OR(WEEKDAY(A4)=1,WEEKDAY(A4)=7,'.'!A:A=A4),TIME(0,0,0),IF((G4*24)>10,TIME(2,0,0),IF((G4*24)<=8,TIME(0,0,0),G4-TIME(8,0,0))))} -> 0 | J4: {=IF(OR(WEEKDAY(A4)=1,WEEKDAY(A4)=7,'.'!A:A=A4),G4,IF((G4*24)>10,IF((G4*24)<=10,TIME(0,0,0),G4-TIME(10,0,0)),TIME(0,0,0)))} -> 0 | K4: =IF((G4*24)=0,TIME(0,0,0),IF((C4*24)<6,TIME(6-(C4*24),0,0),TIME(0,0,0))+IF((F4*24)>22,F4-TIME(22,0,0),TIME(0,0,0))) -> 0 | L4: =IF(A4=" "," ",((H4*24)+(I4*24*1.75)+(J4*24*2)+(K4*24*0.3))) -> 0
A5: 44654 | B5: =A5 -> 44654 | C5: 0 | D5: 0 | E5: 0 | F5: 0 | G5: =IF(A5=" "," ",(D5-C5)+(F5-E5)) -> 0 | H5: {=IF(OR(WEEKDAY(A5)=1,WEEKDAY(A5)=7,'.'!A:A=A5),TIME(0,0,0),IF((G5*24)>8,TIME(8,0,0),G5))} -> 0 | I5: {=IF(OR(WEEKDAY(A5)=1,WEEKDAY(A5)=7,'.'!A:A=A5),TIME(0,0,0),IF((G5*24)>10,TIME(2,0,0),IF((G5*24)<=8,TIME(0,0,0),G5-TIME(8,0,0))))} -> 0 | J5: {=IF(OR(WEEKDAY(A5)=1,WEEKDAY(A5)=7,'.'!A:A=A5),G5,IF((G5*24)>10,IF((G5*24)<=10,TIME(0,0,0),G5-TIME(10,0,0)),TIME(0,0,0)))} -> 0 | K5: =IF((G5*24)=0,TIME(0,0,0),IF((C5*24)<6,TIME(6-(C5*24),0,0),TIME(0,0,0))+IF((F5*24)>22,F5-TIME(22,0,0),TIME(0,0,0))) -> 0 | L5: =IF(A5=" "," ",((H5*24)+(I5*24*1.75)+(J5*24*2)+(K5*24*0.3))) -> 0
A6: 44655 | B6: =A6 -> 44655 | C6: 0 | D6: 0 | E6: 0 | F6: 0 | G6: =IF(A6=" "," ",(D6-C6)+(F6-E6)) -> 0 | H6: {=IF(OR(WEEKDAY(A6)=1,WEEKDAY(A6)=7,'.'!A:A=A6),TIME(0,0,0),IF((G6*24)>8,TIME(8,0,0),G6))} -> 0 | I6: {=IF(OR(WEEKDAY(A6)=1,WEEKDAY(A6)=7,'.'!A:A=A6),TIME(0,0,0),IF((G6*24)>10,TIME(2,0,0),IF((G6*24)<=8,TIME(0,0,0),G6-TIME(8,0,0))))} -> 0 | J6: {=IF(OR(WEEKDAY(A6)=1,WEEKDAY(A6)=7,'.'!A:A=A6),G6,IF((G6*24)>10,IF((G6*24)<=10,TIME(0,0,0),G6-TIME(10,0,0)),TIME(0,0,0)))} -> 0 | K6: =IF((G6*24)=0,TIME(0,0,0),IF((C6*24)<6,TIME(6-(C6*24),0,0),TIME(0,0,0))+IF((F6*24)>22,F6-TIME(22,0,0),TIME(0,0,0))) -> 0 | L6: =IF(A6=" "," ",((H6*24)+(I6*24*1.75)+(J6*24*2)+(K6*24*0.3))) -> 0
A7: 44656 | B7: =A7 -> 44656 | C7: 0 | D7: 0 | E7: 0 | F7: 0 | G7: =IF(A7=" "," ",(D7-C7)+(F7-E7)) -> 0 | H7: {=IF(OR(WEEKDAY(A7)=1,WEEKDAY(A7)=7,'.'!A:A=A7),TIME(0,0,0),IF((G7*24)>8,TIME(8,0,0),G7))} -> 0 | I7: {=IF(OR(WEEKDAY(A7)=1,WEEKDAY(A7)=7,'.'!A:A=A7),TIME(0,0,0),IF((G7*24)>10,TIME(2,0,0),IF((G7*24)<=8,TIME(0,0,0),G7-TIME(8,0,0))))} -> 0 | J7: {=IF(OR(WEEKDAY(A7)=1,WEEKDAY(A7)=7,'.'!A:A=A7),G7,IF((G7*24)>10,IF((G7*24)<=10,TIME(0,0,0),G7-TIME(10,0,0)),TIME(0,0,0)))} -> 0 | K7: =IF((G7*24)=0,TIME(0,0,0),IF((C7*24)<6,TIME(6-(C7*24),0,0),TIME(0,0,0))+IF((F7*24)>22,F7-TIME(22,0,0),TIME(0,0,0))) -> 0 | L7: =IF(A7=" "," ",((H7*24)+(I7*24*1.75)+(J7*24*2)+(K7*24*0.3))) -> 0
A8: 44657 | B8: =A8 -> 44657 | C8: 0 | D8: 0 | E8: 0 | F8: 0 | G8: =IF(A8=" "," ",(D8-C8)+(F8-E8)) -> 0 | H8: {=IF(OR(WEEKDAY(A8)=1,WEEKDAY(A8)=7,'.'!A:A=A8),TIME(0,0,0),IF((G8*24)>8,TIME(8,0,0),G8))} -> 0 | I8: {=IF(OR(WEEKDAY(A8)=1,WEEKDAY(A8)=7,'.'!A:A=A8),TIME(0,0,0),IF((G8*24)>10,TIME(2,0,0),IF((G8*24)<=8,TIME(0,0,0),G8-TIME(8,0,0))))} -> 0 | J8: {=IF(OR(WEEKDAY(A8)=1,WEEKDAY(A8)=7,'.'!A:A=A8),G8,IF((G8*24)>10,IF((G8*24)<=10,TIME(0,0,0),G8-TIME(10,0,0)),TIME(0,0,0)))} -> 0 | K8: =IF((G8*24)=0,TIME(0,0,0),IF((C8*24)<6,TIME(6-(C8*24),0,0),TIME(0,0,0))+IF((F8*24)>22,F8-TIME(22,0,0),TIME(0,0,0))) -> 0 | L8: =IF(A8=" "," ",((H8*24)+(I8*24*1.75)+(J8*24*2)+(K8*24*0.3))) -> 0
A9: 44658 | B9: =A9 -> 44658 | C9: 0 | D9: 0 | E9: 0 | F9: 0 | G9: =IF(A9=" "," ",(D9-C9)+(F9-E9)) -> 0 | H9: {=IF(OR(WEEKDAY(A9)=1,WEEKDAY(A9)=7,'.'!A:A=A9),TIME(0,0,0),IF((G9*24)>8,TIME(8,0,0),G9))} -> 0 | I9: {=IF(OR(WEEKDAY(A9)=1,WEEKDAY(A9)=7,'.'!A:A=A9),TIME(0,0,0),IF((G9*24)>10,TIME(2,0,0),IF((G9*24)<=8,TIME(0,0,0),G9-TIME(8,0,0))))} -> 0 | J9: {=IF(OR(WEEKDAY(A9)=1,WEEKDAY(A9)=7,'.'!A:A=A9),G9,IF((G9*24)>10,IF((G9*24)<=10,TIME(0,0,0),G9-TIME(10,0,0)),TIME(0,0,0)))} -> 0 | K9: =IF((G9*24)=0,TIME(0,0,0),IF((C9*24)<6,TIME(6-(C9*24),0,0),TIME(0,0,0))+IF((F9*24)>22,F9-TIME(22,0,0),TIME(0,0,0))) -> 0 | L9: =IF(A9=" "," ",((H9*24)+(I9*24*1.75)+(J9*24*2)+(K9*24*0.3))) -> 0
A10: 44659 | B10: =A10 -> 44659 | C10: 0 | D10: 0 | E10: 0 | F10: 0 | G10: =IF(A10=" "," ",(D10-C10)+(F10-E10)) -> 0 | H10: {=IF(OR(WEEKDAY(A10)=1,WEEKDAY(A10)=7,'.'!A:A=A10),TIME(0,0,0),IF((G10*24)>8,TIME(8,0,0),G10))} -> 0 | I10: {=IF(OR(WEEKDAY(A10)=1,WEEKDAY(A10)=7,'.'!A:A=A10),TIME(0,0,0),IF((G10*24)>10,TIME(2,0,0),IF((G10*24)<=8,TIME(0,0,0),G10-TIME(8,0,0))))} -> 0 | J10: {=IF(OR(WEEKDAY(A10)=1,WEEKDAY(A10)=7,'.'!A:A=A10),G10,IF((G10*24)>10,IF((G10*24)<=10,TIME(0,0,0),G10-TIME(10,0,0)),TIME(0,0,0)))} -> 0 | K10: =IF((G10*24)=0,TIME(0,0,0),IF((C10*24)<6,TIME(6-(C10*24),0,0),TIME(0,0,0))+IF((F10*24)>22,F10-TIME(22,0,0),TIME(0,0,0))) -> 0 | L10: =IF(A10=" "," ",((H10*24)+(I10*24*1.75)+(J10*24*2)+(K10*24*0.3))) -> 0
A11: 44660 | B11: =A11 -> 44660 | C11: 0 | D11: 0 | E11: 0 | F11: 0 | G11: =IF(A11=" "," ",(D11-C11)+(F11-E11)) -> 0 | H11: {=IF(OR(WEEKDAY(A11)=1,WEEKDAY(A11)=7,'.'!A:A=A11),TIME(0,0,0),IF((G11*24)>8,TIME(8,0,0),G11))} -> 0 | I11: {=IF(OR(WEEKDAY(A11)=1,WEEKDAY(A11)=7,'.'!A:A=A11),TIME(0,0,0),IF((G11*24)>10,TIME(2,0,0),IF((G11*24)<=8,TIME(0,0,0),G11-TIME(8,0,0))))} -> 0 | J11: {=IF(OR(WEEKDAY(A11)=1,WEEKDAY(A11)=7,'.'!A:A=A11),G11,IF((G11*24)>10,IF((G11*24)<=10,TIME(0,0,0),G11-TIME(10,0,0)),TIME(0,0,0)))} -> 0 | K11: =IF((G11*24)=0,TIME(0,0,0),IF((C11*24)<6,TIME(6-(C11*24),0,0),TIME(0,0,0))+IF((F11*24)>22,F11-TIME(22,0,0),TIME(0,0,0))) -> 0 | L11: =IF(A11=" "," ",((H11*24)+(I11*24*1.75)+(J11*24*2)+(K11*24*0.3))) -> 0
A12: 44661 | B12: =A12 -> 44661 | C12: 0 | D12: 0 | E12: 0 | F12: 0 | G12: =IF(A12=" "," ",(D12-C12)+(F12-E12)) -> 0 | H12: {=IF(OR(WEEKDAY(A12)=1,WEEKDAY(A12)=7,'.'!A:A=A12),TIME(0,0,0),IF((G12*24)>8,TIME(8,0,0),G12))} -> 0 | I12: {=IF(OR(WEEKDAY(A12)=1,WEEKDAY(A12)=7,'.'!A:A=A12),TIME(0,0,0),IF((G12*24)>10,TIME(2,0,0),IF((G12*24)<=8,TIME(0,0,0),G12-TIME(8,0,0))))} -> 0 | J12: {=IF(OR(WEEKDAY(A12)=1,WEEKDAY(A12)=7,'.'!A:A=A12),G12,IF((G12*24)>10,IF((G12*24)<=10,TIME(0,0,0),G12-TIME(10,0,0)),TIME(0,0,0)))} -> 0 | K12: =IF((G12*24)=0,TIME(0,0,0),IF((C12*24)<6,TIME(6-(C12*24),0,0),TIME(0,0,0))+IF((F12*24)>22,F12-TIME(22,0,0),TIME(0,0,0))) -> 0 | L12: =IF(A12=" "," ",((H12*24)+(I12*24*1.75)+(J12*24*2)+(K12*24*0.3))) -> 0
A13: 44662 | B13: =A13 -> 44662 | C13: 0 | D13: 0 | E13: 0 | F13: 0 | G13: =IF(A13=" "," ",(D13-C13)+(F13-E13)) -> 0 | H13: {=IF(OR(WEEKDAY(A13)=1,WEEKDAY(A13)=7,'.'!A:A=A13),TIME(0,0,0),IF((G13*24)>8,TIME(8,0,0),G13))} -> 0 | I13: {=IF(OR(WEEKDAY(A13)=1,WEEKDAY(A13)=7,'.'!A:A=A13),TIME(0,0,0),IF((G13*24)>10,TIME(2,0,0),IF((G13*24)<=8,TIME(0,0,0),G13-TIME(8,0,0))))} -> 0 | J13: {=IF(OR(WEEKDAY(A13)=1,WEEKDAY(A13)=7,'.'!A:A=A13),G13,IF((G13*24)>10,IF((G13*24)<=10,TIME(0,0,0),G13-TIME(10,0,0)),TIME(0,0,0)))} -> 0 | K13: =IF((G13*24)=0,TIME(0,0,0),IF((C13*24)<6,TIME(6-(C13*24),0,0),TIME(0,0,0))+IF((F13*24)>22,F13-TIME(22,0,0),TIME(0,0,0))) -> 0 | L13: =IF(A13=" "," ",((H13*24)+(I13*24*1.75)+(J13*24*2)+(K13*24*0.3))) -> 0
A14: 44663 | B14: =A14 -> 44663 | C14: 0 | D14: 0 | E14: 0 | F14: 0 | G14: =IF(A14=" "," ",(D14-C14)+(F14-E14)) -> 0 | H14: {=IF(OR(WEEKDAY(A14)=1,WEEKDAY(A14)=7,'.'!A:A=A14),TIME(0,0,0),IF((G14*24)>8,TIME(8,0,0),G14))} -> 0 | I14: {=IF(OR(WEEKDAY(A14)=1,WEEKDAY(A14)=7,'.'!A:A=A14),TIME(0,0,0),IF((G14*24)>10,TIME(2,0,0),IF((G14*24)<=8,TIME(0,0,0),G14-TIME(8,0,0))))} -> 0 | J14: {=IF(OR(WEEKDAY(A14)=1,WEEKDAY(A14)=7,'.'!A:A=A14),G14,IF((G14*24)>10,IF((G14*24)<=10,TIME(0,0,0),G14-TIME(10,0,0)),TIME(0,0,0)))} -> 0 | K14: =IF((G14*24)=0,TIME(0,0,0),IF((C14*24)<6,TIME(6-(C14*24),0,0),TIME(0,0,0))+IF((F14*24)>22,F14-TIME(22,0,0),TIME(0,0,0))) -> 0 | L14: =IF(A14=" "," ",((H14*24)+(I14*24*1.75)+(J14*24*2)+(K14*24*0.3))) -> 0
... A16: 44665 | B16: =A16 -> 44665 | C16: 0 | D16: 0 | E16: 0 | F16: 0 | G16: =IF(A16=" "," ",(D16-C16)+(F16-E16)) -> 0 | H16: {=IF(OR(WEEKDAY(A16)=1,WEEKDAY(A16)=7,'.'!A:A=A16),TIME(0,0,0),IF((G16*24)>8,TIME(8,0,0),G16))} -> 0 | I16: {=IF(OR(WEEKDAY(A16)=1,WEEKDAY(A16)=7,'.'!A:A=A16),TIME(0,0,0),IF((G16*24)>10,TIME(2,0,0),IF((G16*24)<=8,TIME(0,0,0),G16-TIME(8,0,0))))} -> 0 | J16: {=IF(OR(WEEKDAY(A16)=1,WEEKDAY(A16)=7,'.'!A:A=A16),G16,IF((G16*24)>10,IF((G16*24)<=10,TIME(0,0,0),G16-TIME(10,0,0)),TIME(0,0,0)))} -> 0 | K16: =IF((G16*24)=0,TIME(0,0,0),IF((C16*24)<6,TIME(6-(C16*24),0,0),TIME(0,0,0))+IF((F16*24)>22,F16-TIME(22,0,0),TIME(0,0,0))) -> 0 | L16: =IF(A16=" "," ",((H16*24)+(I16*24*1.75)+(J16*24*2)+(K16*24*0.3))) -> 0
A17: 44666 | B17: =A17 -> 44666 | C17: 0 | D17: 0 | E17: 0 | F17: 0 | G17: =IF(A17=" "," ",(D17-C17)+(F17-E17)) -> 0 | H17: {=IF(OR(WEEKDAY(A17)=1,WEEKDAY(A17)=7,'.'!A:A=A17),TIME(0,0,0),IF((G17*24)>8,TIME(8,0,0),G17))} -> 0 | I17: {=IF(OR(WEEKDAY(A17)=1,WEEKDAY(A17)=7,'.'!A:A=A17),TIME(0,0,0),IF((G17*24)>10,TIME(2,0,0),IF((G17*24)<=8,TIME(0,0,0),G17-TIME(8,0,0))))} -> 0 | J17: {=IF(OR(WEEKDAY(A17)=1,WEEKDAY(A17)=7,'.'!A:A=A17),G17,IF((G17*24)>10,IF((G17*24)<=10,TIME(0,0,0),G17-TIME(10,0,0)),TIME(0,0,0)))} -> 0 | K17: =IF((G17*24)=0,TIME(0,0,0),IF((C17*24)<6,TIME(6-(C17*24),0,0),TIME(0,0,0))+IF((F17*24)>22,F17-TIME(22,0,0),TIME(0,0,0))) -> 0 | L17: =IF(A17=" "," ",((H17*24)+(I17*24*1.75)+(J17*24*2)+(K17*24*0.3))) -> 0 | M17: Sexta-feira Santa
A18: 44667 | B18: =A18 -> 44667 | C18: 0 | D18: 0 | E18: 0 | F18: 0 | G18: =IF(A18=" "," ",(D18-C18)+(F18-E18)) -> 0 | H18: {=IF(OR(WEEKDAY(A18)=1,WEEKDAY(A18)=7,'.'!A:A=A18),TIME(0,0,0),IF((G18*24)>8,TIME(8,0,0),G18))} -> 0 | I18: {=IF(OR(WEEKDAY(A18)=1,WEEKDAY(A18)=7,'.'!A:A=A18),TIME(0,0,0),IF((G18*24)>10,TIME(2,0,0),IF((G18*24)<=8,TIME(0,0,0),G18-TIME(8,0,0))))} -> 0 | J18: {=IF(OR(WEEKDAY(A18)=1,WEEKDAY(A18)=7,'.'!A:A=A18),G18,IF((G18*24)>10,IF((G18*24)<=10,TIME(0,0,0),G18-TIME(10,0,0)),TIME(0,0,0)))} -> 0 | K18: =IF((G18*24)=0,TIME(0,0,0),IF((C18*24)<6,TIME(6-(C18*24),0,0),TIME(0,0,0))+IF((F18*24)>22,F18-TIME(22,0,0),TIME(0,0,0))) -> 0 | L18: =IF(A18=" "," ",((H18*24)+(I18*24*1.75)+(J18*24*2)+(K18*24*0.3))) -> 0
A19: 44668 | B19: =A19 -> 44668 | C19: 0 | D19: 0 | E19: 0 | F19: 0 | G19: =IF(A19=" "," ",(D19-C19)+(F19-E19)) -> 0 | H19: {=IF(OR(WEEKDAY(A19)=1,WEEKDAY(A19)=7,'.'!A:A=A19),TIME(0,0,0),IF((G19*24)>8,TIME(8,0,0),G19))} -> 0 | I19: {=IF(OR(WEEKDAY(A19)=1,WEEKDAY(A19)=7,'.'!A:A=A19),TIME(0,0,0),IF((G19*24)>10,TIME(2,0,0),IF((G19*24)<=8,TIME(0,0,0),G19-TIME(8,0,0))))} -> 0 | J19: {=IF(OR(WEEKDAY(A19)=1,WEEKDAY(A19)=7,'.'!A:A=A19),G19,IF((G19*24)>10,IF((G19*24)<=10,TIME(0,0,0),G19-TIME(10,0,0)),TIME(0,0,0)))} -> 0 | K19: =IF((G19*24)=0,TIME(0,0,0),IF((C19*24)<6,TIME(6-(C19*24),0,0),TIME(0,0,0))+IF((F19*24)>22,F19-TIME(22,0,0),TIME(0,0,0))) -> 0 | L19: =IF(A19=" "," ",((H19*24)+(I19*24*1.75)+(J19*24*2)+(K19*24*0.3))) -> 0 | M19: Páscoa
A20: 44669 | B20: =A20 -> 44669 | C20: 0 | D20: 0 | E20: 0 | F20: 0 | G20: =IF(A20=" "," ",(D20-C20)+(F20-E20)) -> 0 | H20: {=IF(OR(WEEKDAY(A20)=1,WEEKDAY(A20)=7,'.'!A:A=A20),TIME(0,0,0),IF((G20*24)>8,TIME(8,0,0),G20))} -> 0 | I20: {=IF(OR(WEEKDAY(A20)=1,WEEKDAY(A20)=7,'.'!A:A=A20),TIME(0,0,0),IF((G20*24)>10,TIME(2,0,0),IF((G20*24)<=8,TIME(0,0,0),G20-TIME(8,0,0))))} -> 0 | J20: {=IF(OR(WEEKDAY(A20)=1,WEEKDAY(A20)=7,'.'!A:A=A20),G20,IF((G20*24)>10,IF((G20*24)<=10,TIME(0,0,0),G20-TIME(10,0,0)),TIME(0,0,0)))} -> 0 | K20: =IF((G20*24)=0,TIME(0,0,0),IF((C20*24)<6,TIME(6-(C20*24),0,0),TIME(0,0,0))+IF((F20*24)>22,F20-TIME(22,0,0),TIME(0,0,0))) -> 0 | L20: =IF(A20=" "," ",((H20*24)+(I20*24*1.75)+(J20*24*2)+(K20*24*0.3))) -> 0
A21: 44670 | B21: =A21 -> 44670 | C21: 0 | D21: 0 | E21: 0 | F21: 0 | G21: =IF(A21=" "," ",(D21-C21)+(F21-E21)) -> 0 | H21: {=IF(OR(WEEKDAY(A21)=1,WEEKDAY(A21)=7,'.'!A:A=A21),TIME(0,0,0),IF((G21*24)>8,TIME(8,0,0),G21))} -> 0 | I21: {=IF(OR(WEEKDAY(A21)=1,WEEKDAY(A21)=7,'.'!A:A=A21),TIME(0,0,0),IF((G21*24)>10,TIME(2,0,0),IF((G21*24)<=8,TIME(0,0,0),G21-TIME(8,0,0))))} -> 0 | J21: {=IF(OR(WEEKDAY(A21)=1,WEEKDAY(A21)=7,'.'!A:A=A21),G21,IF((G21*24)>10,IF((G21*24)<=10,TIME(0,0,0),G21-TIME(10,0,0)),TIME(0,0,0)))} -> 0 | K21: =IF((G21*24)=0,TIME(0,0,0),IF((C21*24)<6,TIME(6-(C21*24),0,0),TIME(0,0,0))+IF((F21*24)>22,F21-TIME(22,0,0),TIME(0,0,0))) -> 0 | L21: =IF(A21=" "," ",((H21*24)+(I21*24*1.75)+(J21*24*2)+(K21*24*0.3))) -> 0
A22: 44671 | B22: =A22 -> 44671 | C22: 0 | D22: 0 | E22: 0 | F22: 0 | G22: =IF(A22=" "," ",(D22-C22)+(F22-E22)) -> 0 | H22: {=IF(OR(WEEKDAY(A22)=1,WEEKDAY(A22)=7,'.'!A:A=A22),TIME(0,0,0),IF((G22*24)>8,TIME(8,0,0),G22))} -> 0 | I22: {=IF(OR(WEEKDAY(A22)=1,WEEKDAY(A22)=7,'.'!A:A=A22),TIME(0,0,0),IF((G22*24)>10,TIME(2,0,0),IF((G22*24)<=8,TIME(0,0,0),G22-TIME(8,0,0))))} -> 0 | J22: {=IF(OR(WEEKDAY(A22)=1,WEEKDAY(A22)=7,'.'!A:A=A22),G22,IF((G22*24)>10,IF((G22*24)<=10,TIME(0,0,0),G22-TIME(10,0,0)),TIME(0,0,0)))} -> 0 | K22: =IF((G22*24)=0,TIME(0,0,0),IF((C22*24)<6,TIME(6-(C22*24),0,0),TIME(0,0,0))+IF((F22*24)>22,F22-TIME(22,0,0),TIME(0,0,0))) -> 0 | L22: =IF(A22=" "," ",((H22*24)+(I22*24*1.75)+(J22*24*2)+(K22*24*0.3))) -> 0
A23: 44672 | B23: =A23 -> 44672 | C23: 0 | D23: 0 | E23: 0 | F23: 0 | G23: =IF(A23=" "," ",(D23-C23)+(F23-E23)) -> 0 | H23: {=IF(OR(WEEKDAY(A23)=1,WEEKDAY(A23)=7,'.'!A:A=A23),TIME(0,0,0),IF((G23*24)>8,TIME(8,0,0),G23))} -> 0 | I23: {=IF(OR(WEEKDAY(A23)=1,WEEKDAY(A23)=7,'.'!A:A=A23),TIME(0,0,0),IF((G23*24)>10,TIME(2,0,0),IF((G23*24)<=8,TIME(0,0,0),G23-TIME(8,0,0))))} -> 0 | J23: {=IF(OR(WEEKDAY(A23)=1,WEEKDAY(A23)=7,'.'!A:A=A23),G23,IF((G23*24)>10,IF((G23*24)<=10,TIME(0,0,0),G23-TIME(10,0,0)),TIME(0,0,0)))} -> 0 | K23: =IF((G23*24)=0,TIME(0,0,0),IF((C23*24)<6,TIME(6-(C23*24),0,0),TIME(0,0,0))+IF((F23*24)>22,F23-TIME(22,0,0),TIME(0,0,0))) -> 0 | L23: =IF(A23=" "," ",((H23*24)+(I23*24*1.75)+(J23*24*2)+(K23*24*0.3))) -> 0 | M23: Tiradentes
A24: 44673 | B24: =A24 -> 44673 | C24: 0 | D24: 0 | E24: 0 | F24: 0 | G24: =IF(A24=" "," ",(D24-C24)+(F24-E24)) -> 0 | H24: {=IF(OR(WEEKDAY(A24)=1,WEEKDAY(A24)=7,'.'!A:A=A24),TIME(0,0,0),IF((G24*24)>8,TIME(8,0,0),G24))} -> 0 | I24: {=IF(OR(WEEKDAY(A24)=1,WEEKDAY(A24)=7,'.'!A:A=A24),TIME(0,0,0),IF((G24*24)>10,TIME(2,0,0),IF((G24*24)<=8,TIME(0,0,0),G24-TIME(8,0,0))))} -> 0 | J24: {=IF(OR(WEEKDAY(A24)=1,WEEKDAY(A24)=7,'.'!A:A=A24),G24,IF((G24*24)>10,IF((G24*24)<=10,TIME(0,0,0),G24-TIME(10,0,0)),TIME(0,0,0)))} -> 0 | K24: =IF((G24*24)=0,TIME(0,0,0),IF((C24*24)<6,TIME(6-(C24*24),0,0),TIME(0,0,0))+IF((F24*24)>22,F24-TIME(22,0,0),TIME(0,0,0))) -> 0 | L24: =IF(A24=" "," ",((H24*24)+(I24*24*1.75)+(J24*24*2)+(K24*24*0.3))) -> 0
A25: 44674 | B25: =A25 -> 44674 | C25: 0 | D25: 0 | E25: 0 | F25: 0 | G25: =IF(A25=" "," ",(D25-C25)+(F25-E25)) -> 0 | H25: {=IF(OR(WEEKDAY(A25)=1,WEEKDAY(A25)=7,'.'!A:A=A25),TIME(0,0,0),IF((G25*24)>8,TIME(8,0,0),G25))} -> 0 | I25: {=IF(OR(WEEKDAY(A25)=1,WEEKDAY(A25)=7,'.'!A:A=A25),TIME(0,0,0),IF((G25*24)>10,TIME(2,0,0),IF((G25*24)<=8,TIME(0,0,0),G25-TIME(8,0,0))))} -> 0 | J25: {=IF(OR(WEEKDAY(A25)=1,WEEKDAY(A25)=7,'.'!A:A=A25),G25,IF((G25*24)>10,IF((G25*24)<=10,TIME(0,0,0),G25-TIME(10,0,0)),TIME(0,0,0)))} -> 0 | K25: =IF((G25*24)=0,TIME(0,0,0),IF((C25*24)<6,TIME(6-(C25*24),0,0),TIME(0,0,0))+IF((F25*24)>22,F25-TIME(22,0,0),TIME(0,0,0))) -> 0 | L25: =IF(A25=" "," ",((H25*24)+(I25*24*1.75)+(J25*24*2)+(K25*24*0.3))) -> 0
A26: 44675 | B26: =A26 -> 44675 | C26: 0 | D26: 0 | E26: 0 | F26: 0 | G26: =IF(A26=" "," ",(D26-C26)+(F26-E26)) -> 0 | H26: {=IF(OR(WEEKDAY(A26)=1,WEEKDAY(A26)=7,'.'!A:A=A26),TIME(0,0,0),IF((G26*24)>8,TIME(8,0,0),G26))} -> 0 | I26: {=IF(OR(WEEKDAY(A26)=1,WEEKDAY(A26)=7,'.'!A:A=A26),TIME(0,0,0),IF((G26*24)>10,TIME(2,0,0),IF((G26*24)<=8,TIME(0,0,0),G26-TIME(8,0,0))))} -> 0 | J26: {=IF(OR(WEEKDAY(A26)=1,WEEKDAY(A26)=7,'.'!A:A=A26),G26,IF((G26*24)>10,IF((G26*24)<=10,TIME(0,0,0),G26-TIME(10,0,0)),TIME(0,0,0)))} -> 0 | K26: =IF((G26*24)=0,TIME(0,0,0),IF((C26*24)<6,TIME(6-(C26*24),0,0),TIME(0,0,0))+IF((F26*24)>22,F26-TIME(22,0,0),TIME(0,0,0))) -> 0 | L26: =IF(A26=" "," ",((H26*24)+(I26*24*1.75)+(J26*24*2)+(K26*24*0.3))) -> 0
A27: 44676 | B27: =A27 -> 44676 | C27: 0 | D27: 0 | E27: 0 | F27: 0 | G27: =IF(A27=" "," ",(D27-C27)+(F27-E27)) -> 0 | H27: {=IF(OR(WEEKDAY(A27)=1,WEEKDAY(A27)=7,'.'!A:A=A27),TIME(0,0,0),IF((G27*24)>8,TIME(8,0,0),G27))} -> 0 | I27: {=IF(OR(WEEKDAY(A27)=1,WEEKDAY(A27)=7,'.'!A:A=A27),TIME(0,0,0),IF((G27*24)>10,TIME(2,0,0),IF((G27*24)<=8,TIME(0,0,0),G27-TIME(8,0,0))))} -> 0 | J27: {=IF(OR(WEEKDAY(A27)=1,WEEKDAY(A27)=7,'.'!A:A=A27),G27,IF((G27*24)>10,IF((G27*24)<=10,TIME(0,0,0),G27-TIME(10,0,0)),TIME(0,0,0)))} -> 0 | K27: =IF((G27*24)=0,TIME(0,0,0),IF((C27*24)<6,TIME(6-(C27*24),0,0),TIME(0,0,0))+IF((F27*24)>22,F27-TIME(22,0,0),TIME(0,0,0))) -> 0 | L27: =IF(A27=" "," ",((H27*24)+(I27*24*1.75)+(J27*24*2)+(K27*24*0.3))) -> 0
A28: 44677 | B28: =A28 -> 44677 | C28: 0 | D28: 0 | E28: 0 | F28: 0 | G28: =IF(A28=" "," ",(D28-C28)+(F28-E28)) -> 0 | H28: {=IF(OR(WEEKDAY(A28)=1,WEEKDAY(A28)=7,'.'!A:A=A28),TIME(0,0,0),IF((G28*24)>8,TIME(8,0,0),G28))} -> 0 | I28: {=IF(OR(WEEKDAY(A28)=1,WEEKDAY(A28)=7,'.'!A:A=A28),TIME(0,0,0),IF((G28*24)>10,TIME(2,0,0),IF((G28*24)<=8,TIME(0,0,0),G28-TIME(8,0,0))))} -> 0 | J28: {=IF(OR(WEEKDAY(A28)=1,WEEKDAY(A28)=7,'.'!A:A=A28),G28,IF((G28*24)>10,IF((G28*24)<=10,TIME(0,0,0),G28-TIME(10,0,0)),TIME(0,0,0)))} -> 0 | K28: =IF((G28*24)=0,TIME(0,0,0),IF((C28*24)<6,TIME(6-(C28*24),0,0),TIME(0,0,0))+IF((F28*24)>22,F28-TIME(22,0,0),TIME(0,0,0))) -> 0 | L28: =IF(A28=" "," ",((H28*24)+(I28*24*1.75)+(J28*24*2)+(K28*24*0.3))) -> 0
A29: 44678 | B29: =A29 -> 44678 | C29: 0 | D29: 0 | E29: 0 | F29: 0 | G29: =IF(A29=" "," ",(D29-C29)+(F29-E29)) -> 0 | H29: {=IF(OR(WEEKDAY(A29)=1,WEEKDAY(A29)=7,'.'!A:A=A29),TIME(0,0,0),IF((G29*24)>8,TIME(8,0,0),G29))} -> 0 | I29: {=IF(OR(WEEKDAY(A29)=1,WEEKDAY(A29)=7,'.'!A:A=A29),TIME(0,0,0),IF((G29*24)>10,TIME(2,0,0),IF((G29*24)<=8,TIME(0,0,0),G29-TIME(8,0,0))))} -> 0 | J29: {=IF(OR(WEEKDAY(A29)=1,WEEKDAY(A29)=7,'.'!A:A=A29),G29,IF((G29*24)>10,IF((G29*24)<=10,TIME(0,0,0),G29-TIME(10,0,0)),TIME(0,0,0)))} -> 0 | K29: =IF((G29*24)=0,TIME(0,0,0),IF((C29*24)<6,TIME(6-(C29*24),0,0),TIME(0,0,0))+IF((F29*24)>22,F29-TIME(22,0,0),TIME(0,0,0))) -> 0 | L29: =IF(A29=" "," ",((H29*24)+(I29*24*1.75)+(J29*24*2)+(K29*24*0.3))) -> 0
A30: 44679 | B30: =A30 -> 44679 | C30: 0 | D30: 0 | E30: 0 | F30: 0 | G30: =IF(A30=" "," ",(D30-C30)+(F30-E30)) -> 0 | H30: {=IF(OR(WEEKDAY(A30)=1,WEEKDAY(A30)=7,'.'!A:A=A30),TIME(0,0,0),IF((G30*24)>8,TIME(8,0,0),G30))} -> 0 | I30: {=IF(OR(WEEKDAY(A30)=1,WEEKDAY(A30)=7,'.'!A:A=A30),TIME(0,0,0),IF((G30*24)>10,TIME(2,0,0),IF((G30*24)<=8,TIME(0,0,0),G30-TIME(8,0,0))))} -> 0 | J30: {=IF(OR(WEEKDAY(A30)=1,WEEKDAY(A30)=7,'.'!A:A=A30),G30,IF((G30*24)>10,IF((G30*24)<=10,TIME(0,0,0),G30-TIME(10,0,0)),TIME(0,0,0)))} -> 0 | K30: =IF((G30*24)=0,TIME(0,0,0),IF((C30*24)<6,TIME(6-(C30*24),0,0),TIME(0,0,0))+IF((F30*24)>22,F30-TIME(22,0,0),TIME(0,0,0))) -> 0 | L30: =IF(A30=" "," ",((H30*24)+(I30*24*1.75)+(J30*24*2)+(K30*24*0.3))) -> 0
A31: 44680 | B31: =A31 -> 44680 | C31: 0 | D31: 0 | E31: 0 | F31: 0 | G31: =IF(A31=" "," ",(D31-C31)+(F31-E31)) -> 0 | H31: {=IF(OR(WEEKDAY(A31)=1,WEEKDAY(A31)=7,'.'!A:A=A31),TIME(0,0,0),IF((G31*24)>8,TIME(8,0,0),G31))} -> 0 | I31: {=IF(OR(WEEKDAY(A31)=1,WEEKDAY(A31)=7,'.'!A:A=A31),TIME(0,0,0),IF((G31*24)>10,TIME(2,0,0),IF((G31*24)<=8,TIME(0,0,0),G31-TIME(8,0,0))))} -> 0 | J31: {=IF(OR(WEEKDAY(A31)=1,WEEKDAY(A31)=7,'.'!A:A=A31),G31,IF((G31*24)>10,IF((G31*24)<=10,TIME(0,0,0),G31-TIME(10,0,0)),TIME(0,0,0)))} -> 0 | K31: =IF((G31*24)=0,TIME(0,0,0),IF((C31*24)<6,TIME(6-(C31*24),0,0),TIME(0,0,0))+IF((F31*24)>22,F31-TIME(22,0,0),TIME(0,0,0))) -> 0 | L31: =IF(A31=" "," ",((H31*24)+(I31*24*1.75)+(J31*24*2)+(K31*24*0.3))) -> 0
A32: 44681 | B32: =A32 -> 44681 | C32: 0 | D32: 0 | E32: 0 | F32: 0 | G32: =IF(A32=" "," ",(D32-C32)+(F32-E32)) -> 0 | H32: {=IF(OR(WEEKDAY(A32)=1,WEEKDAY(A32)=7,'.'!A:A=A32),TIME(0,0,0),IF((G32*24)>8,TIME(8,0,0),G32))} -> 0 | I32: {=IF(OR(WEEKDAY(A32)=1,WEEKDAY(A32)=7,'.'!A:A=A32),TIME(0,0,0),IF((G32*24)>10,TIME(2,0,0),IF((G32*24)<=8,TIME(0,0,0),G32-TIME(8,0,0))))} -> 0 | J32: {=IF(OR(WEEKDAY(A32)=1,WEEKDAY(A32)=7,'.'!A:A=A32),G32,IF((G32*24)>10,IF((G32*24)<=10,TIME(0,0,0),G32-TIME(10,0,0)),TIME(0,0,0)))} -> 0 | K32: =IF((G32*24)=0,TIME(0,0,0),IF((C32*24)<6,TIME(6-(C32*24),0,0),TIME(0,0,0))+IF((F32*24)>22,F32-TIME(22,0,0),TIME(0,0,0))) -> 0 | L32: =IF(A32=" "," ",((H32*24)+(I32*24*1.75)+(J32*24*2)+(K32*24*0.3))) -> 0
A34: Totais | G34: =SUM(G3:G33)*24 -> 0 | H34: =SUM(H3:H33)*24 -> 0 | I34: =SUM(I3:I33)*24 -> 0 | J34: =SUM(J3:J33)*24 -> 0 | K34: =SUM(K3:K33)*24 -> 0
A35: Total de horas carregadas com adicionais | H35: =H34*1 -> 0 | I35: =I34*1.75 -> 0 | J35: =J34*2 -> 0 | K35: =K34*0.3 -> 0 | L35: =SUM(L3:L33) -> 0
A37: APONTAMENTO DE HORAS
A38: Nome
A39: =Janeiro_22!A39 -> COLOQUE SEU NOME COMPLETO AQUI!
A40: Empresa | G40: Cliente
A41: GTI Solution
A42: Projeto(s) | G42: Data Inicial | I42: Data Final
G43: 44652 | I43: 44681
A45: Legenda
...

Sheet Maio_22
A1: Dia | B1: Dia da Semana | C1: Entrada | D1: Almoço | E1: Retorno | F1: Saída | G1: Total Horas | H1: Horas Normais | I1: Horas 75% | J1: Horas 100% | K1: Adic. Noturno | L1: Convert | M1: Descrição das Atividades
